Workbook

Sheet قوائم_النطاقات
A1: الكل | B1: الكل
A2: الإدارة العامة - القدس | B2: 01
A3: البرنامج الدولي | B3: 02
A4: العلاقات العامة | B4: 03
A5: دائرة التخطيط والجودة | B5: 04
A6: شؤون الطلبة | B6: 05
A7: عمادة الدراسات العليا والبحث العلمي_compressed (1) | B7: 06
A8: عمادة القبول والتسجيل والامتحانات_compressed (1) | B8: 07
A9: فرع الخليل | B9: 08
A10: فرع القدس | B10: 09
A11: فرع بيت لحم | B11: 10
A12: فرع جنين | B12: 11
A13: فرع دورا | B13: 12
A14: فرع رام الله والبيرة
A15: فرع سلفيت
A16: فرع طوباس
A17: فرع طولكرم
A18: فرع قلقيلية
A19: فرع نابلس
A20: فـــرع يــطـــا
A21: مركز التعليم الرقمي
A22: مركز التعليم المستمر وخدمة المجتمع
A23: مركز تكنولوجيا المعلومات

Sheet البيانات_الأساسية
A1: الفرع | B1: اسم الموظف | C1: إجمالي الدقائق | D1: إجمالي حالات التأخير | E1: إجمالي الساعات | F1: متوسط دقائق التأخير | G1: الأشهر المسجلة | H1: Match_Flag | I1: Running_Count | J1: دقائق_01 | K1: دقائق_02 | L1: دقائق_03 | M1: دقائق_04 | N1: دقائق_05 | O1: دقائق_06 | P1: دقائق_07 | Q1: دقائق_08 | R1: دقائق_09 | S1: دقائق_10 | T1: دقائق_11 | U1: دقائق_12 | V1: حالات_01 | W1: حالات_02 | X1: حالات_03 | Y1: حالات_04 | Z1: حالات_05 | AA1: حالات_06 | AB1: حالات_07 | AC1: حالات_08 | AD1: حالات_09 | AE1: حالات_10 | AF1: حالات_11 | AG1: حالات_12 | AH1: كلي_الأحد | AI1: كلي_الاثنين | AJ1: كلي_الثلاثاء | AK1: كلي_الأربعاء | AL1: كلي_الخميس | AM1: كلي_الجمعة | AN1: كلي_السبت | AO1: يوم_الأحد_01 | AP1: يوم_الأحد_02 | AQ1: يوم_الأحد_03 | AR1: يوم_الأحد_04 | AS1: يوم_الأحد_05 | AT1: يوم_الأحد_06 | AU1: يوم_الأحد_07 | AV1: يوم_الأحد_08 | AW1: يوم_الأحد_09 | AX1: يوم_الأحد_10 | AY1: يوم_الأحد_11 | AZ1: يوم_الأحد_12 | BA1: يوم_الاثنين_01 | BB1: يوم_الاثنين_02 | BC1: يوم_الاثنين_03 | BD1: يوم_الاثنين_04 | BE1: يوم_الاثنين_05 | BF1: يوم_الاثنين_06 | BG1: يوم_الاثنين_07 | BH1: يوم_الاثنين_08 | BI1: يوم_الاثنين_09 | BJ1: يوم_الاثنين_10 | BK1: يوم_الاثنين_11 | BL1: يوم_الاثنين_12 | BM1: يوم_الثلاثاء_01 | BN1: يوم_الثلاثاء_02 | BO1: يوم_الثلاثاء_03 | BP1: يوم_الثلاثاء_04 | BQ1: يوم_الثلاثاء_05 | BR1: يوم_الثلاثاء_06 | BS1: يوم_الثلاثاء_07 | BT1: يوم_الثلاثاء_08 | BU1: يوم_الثلاثاء_09 | BV1: يوم_الثلاثاء_10 | BW1: يوم_الثلاثاء_11 | BX1: يوم_الثلاثاء_12 | BY1: يوم_الأربعاء_01 | BZ1: يوم_الأربعاء_02 | CA1: يوم_الأربعاء_03 | CB1: يوم_الأربعاء_04 | CC1: يوم_الأربعاء_05 | CD1: يوم_الأربعاء_06 | CE1: يوم_الأربعاء_07 | CF1: يوم_الأربعاء_08 | CG1: يوم_الأربعاء_09 | CH1: يوم_الأربعاء_10 | CI1: يوم_الأربعاء_11 | CJ1: يوم_الأربعاء_12 | CK1: يوم_الخميس_01 | CL1: يوم_الخميس_02 | CM1: يوم_الخميس_03 | CN1: يوم_الخميس_04 | CO1: يوم_الخميس_05 | CP1: يوم_الخميس_06 | CQ1: يوم_الخميس_07 | CR1: يوم_الخميس_08 | CS1: يوم_الخميس_09 | CT1: يوم_الخميس_10 | CU1: يوم_الخميس_11 | CV1: يوم_الخميس_12 | CW1: يوم_الجمعة_01 | CX1: يوم_الجمعة_02 | CY1: يوم_الجمعة_03 | CZ1: يوم_الجمعة_04 | DA1: يوم_الجمعة_05 | DB1: يوم_الجمعة_06 | DC1: يوم_الجمعة_07 | DD1: يوم_الجمعة_08 | DE1: يوم_الجمعة_09 | DF1: يوم_الجمعة_10 | DG1: يوم_الجمعة_11 | DH1: يوم_الجمعة_12 | DI1: يوم_السبت_01 | DJ1: يوم_السبت_02 | DK1: يوم_السبت_03 | DL1: يوم_السبت_04 | DM1: يوم_السبت_05 | DN1: يوم_السبت_06 | DO1: يوم_السبت_07 | DP1: يوم_السبت_08 | DQ1: يوم_السبت_09 | DR1: يوم_السبت_10 | DS1: يوم_السبت_11 | DT1: يوم_السبت_12
A2: فرع رام الله والبيرة | B2: عز الدين محمد مصطفى أبو نزهة | C2: 7969 | D2: 90 | E2: 132.82 | F2: 88.54 | G2: 01، 02، 03، 04، 05، 06، 07 | H2: =IF(AND(OR(لوحة_القيادة!$C$4="الكل", A2=لوحة_القيادة!$C$4), IF(لوحة_القيادة!$C$5="الكل", TRUE, INDEX($V2:$AG2, 1, VALUE(لوحة_القيادة!$C$5))>0)), 1, 0) -> 0 | I2: =IF(H2=1, SUM($H$2:H2), "") -> 0 | J2: 971 | K2: 1116 | L2: 934 | M2: 1600 | N2: 1373 | O2: 1518 | P2: 457 | Q2: 0 | R2: 0 | S2: 0 | T2: 0 | U2: 0 | V2: 12 | W2: 16 | X2: 9 | Y2: 17 | Z2: 17 | AA2: 14 | AB2: 5 | AC2: 0 | AD2: 0 | AE2: 0 | AF2: 0 | AG2: 16 | AH2: 22 | AI2: 19 | AJ2: 22 | AK2: 0 | AL2: 0 | AM2: 11 | AN2: 2 | AO2: 4 | AP2: 1 | AQ2: 3 | AR2: 4 | AS2: 1 | AT2: 1 | AU2: 0 | AV2: 0 | AW2: 0 | AX2: 0 | AY2: 0 | AZ2: 4 | BA2: 4 | BB2: 2 | BC2: 4 | BD2: 3 | BE2: 4 | BF2: 1 | BG2: 0 | BH2: 0 | BI2: 0 | BJ2: 0 | BK2: 0 | BL2: 3 | BM2: 3 | BN2: 3 | BO2: 3 | BP2: 3 | BQ2: 3 | BR2: 1 | BS2: 0 | BT2: 0 | BU2: 0 | BV2: 0 | BW2: 0 | BX2: 3 | BY2: 3 | BZ2: 3 | CA2: 4 | CB2: 3 | CC2: 4 | CD2: 2 | CE2: 0 | CF2: 0 | CG2: 0 | CH2: 0 | CI2: 0 | CJ2: 0 | CK2: 0 | CL2: 0 | CM2: 0 | CN2: 0 | CO2: 0 | CP2: 0 | CQ2: 0 | CR2: 0 | CS2: 0 | CT2: 0 | CU2: 0 | CV2: 0 | CW2: 0 | CX2: 0 | CY2: 0 | CZ2: 0 | DA2: 0 | DB2: 0 | DC2: 0 | DD2: 0 | DE2: 0 | DF2: 0 | DG2: 0 | DH2: 0 | DI2: 2 | DJ2: 0 | DK2: 3 | DL2: 4 | DM2: 2 | DN2: 0 | DO2: 0 | DP2: 0 | DQ2: 0 | DR2: 0 | DS2: 0
A3: فرع رام الله والبيرة | B3: محمد رزق رشيد دارأحمد | C3: 6358 | D3: 76 | E3: 105.97 | F3: 83.66 | G3: 01، 02، 03، 04، 05، 06، 07 | H3: =IF(AND(OR(لوحة_القيادة!$C$4="الكل", A3=لوحة_القيادة!$C$4), IF(لوحة_القيادة!$C$5="الكل", TRUE, INDEX($V3:$AG3, 1, VALUE(لوحة_القيادة!$C$5))>0)), 1, 0) -> 0 | I3: =IF(H3=1, SUM($H$2:H3), "") -> 0 | J3: 1237 | K3: 841 | L3: 651 | M3: 1237 | N3: 915 | O3: 1304 | P3: 173 | Q3: 0 | R3: 0 | S3: 0 | T3: 0 | U3: 0 | V3: 14 | W3: 12 | X3: 9 | Y3: 12 | Z3: 13 | AA3: 14 | AB3: 2 | AC3: 0 | AD3: 0 | AE3: 0 | AF3: 0 | AG3: 18 | AH3: 21 | AI3: 16 | AJ3: 14 | AK3: 0 | AL3: 0 | AM3: 7 | AN3: 2 | AO3: 4 | AP3: 1 | AQ3: 3 | AR3: 4 | AS3: 4 | AT3: 0 | AU3: 0 | AV3: 0 | AW3: 0 | AX3: 0 | AY3: 0 | AZ3: 3 | BA3: 3 | BB3: 3 | BC3: 3 | BD3: 3 | BE3: 5 | BF3: 1 | BG3: 0 | BH3: 0 | BI3: 0 | BJ3: 0 | BK3: 0 | BL3: 3 | BM3: 1 | BN3: 3 | BO3: 3 | BP3: 2 | BQ3: 3 | BR3: 1 | BS3: 0 | BT3: 0 | BU3: 0 | BV3: 0 | BW3: 0 | BX3: 3 | BY3: 3 | BZ3: 2 | CA3: 2 | CB3: 3 | CC3: 1 | CD3: 0 | CE3: 0 | CF3: 0 | CG3: 0 | CH3: 0 | CI3: 0 | CJ3: 0 | CK3: 0 | CL3: 0 | CM3: 0 | CN3: 0 | CO3: 0 | CP3: 0 | CQ3: 0 | CR3: 0 | CS3: 0 | CT3: 0 | CU3: 0 | CV3: 0 | CW3: 0 | CX3: 0 | CY3: 0 | CZ3: 0 | DA3: 0 | DB3: 0 | DC3: 0 | DD3: 0 | DE3: 0 | DF3: 0 | DG3: 0 | DH3: 3 | DI3: 1 | DJ3: 0 | DK3: 1 | DL3: 1 | DM3: 1 | DN3: 0 | DO3: 0 | DP3: 0 | DQ3: 0 | DR3: 0 | DS3: 0
A4: الإدارة العامة - القدس | B4: رامي نجيب محمود خليل | C4: 5561 | D4: 73 | E4: 92.68 | F4: 76.18 | G4: 01، 02، 03، 04، 05، 06، 07 | H4: =IF(AND(OR(لوحة_القيادة!$C$4="الكل", A4=لوحة_القيادة!$C$4), IF(لوحة_القيادة!$C$5="الكل", TRUE, INDEX($V4:$AG4, 1, VALUE(لوحة_القيادة!$C$5))>0)), 1, 0) -> 0 | I4: =IF(H4=1, SUM($H$2:H4), "") -> 0 | J4: 1290 | K4: 822 | L4: 243 | M4: 805 | N4: 977 | O4: 1062 | P4: 362 | Q4: 0 | R4: 0 | S4: 0 | T4: 0 | U4: 0 | V4: 14 | W4: 12 | X4: 4 | Y4: 12 | Z4: 13 | AA4: 14 | AB4: 4 | AC4: 0 | AD4: 0 | AE4: 0 | AF4: 0 | AG4: 14 | AH4: 17 | AI4: 13 | AJ4: 18 | AK4: 0 | AL4: 0 | AM4: 11 | AN4: 2 | AO4: 2 | AP4: 1 | AQ4: 2 | AR4: 3 | AS4: 3 | AT4: 1 | AU4: 0 | AV4: 0 | AW4: 0 | AX4: 0 | AY4: 0 | AZ4: 3 | BA4: 3 | BB4: 1 | BC4: 4 | BD4: 3 | BE4: 2 | BF4: 1 | BG4: 0 | BH4: 0 | BI4: 0 | BJ4: 0 | BK4: 0 | BL4: 2 | BM4: 2 | BN4: 1 | BO4: 3 | BP4: 1 | BQ4: 4 | BR4: 0 | BS4: 0 | BT4: 0 | BU4: 0 | BV4: 0 | BW4: 0 | BX4: 3 | BY4: 3 | BZ4: 1 | CA4: 2 | CB4: 3 | CC4: 4 | CD4: 2 | CE4: 0 | CF4: 0 | CG4: 0 | CH4: 0 | CI4: 0 | CJ4: 0 | CK4: 0 | CL4: 0 | CM4: 0 | CN4: 0 | CO4: 0 | CP4: 0 | CQ4: 0 | CR4: 0 | CS4: 0 | CT4: 0 | CU4: 0 | CV4: 0 | CW4: 0 | CX4: 0 | CY4: 0 | CZ4: 0 | DA4: 0 | DB4: 0 | DC4: 0 | DD4: 0 | DE4: 0 | DF4: 0 | DG4: 0 | DH4: 4 | DI4: 2 | DJ4: 0 | DK4: 1 | DL4: 3 | DM4: 1 | DN4: 0 | DO4: 0 | DP4: 0 | DQ4: 0 | DR4: 0 | DS4: 0
A5: مركز التعليم الرقمي | B5: ابراهيم محمد ابراهيم ابو تركي | C5: 4976 | D5: 105 | E5: 82.93 | F5: 47.39 | G5: 01، 02، 03، 04، 05، 06، 07 | H5: =IF(AND(OR(لوحة_القيادة!$C$4="الكل", A5=لوحة_القيادة!$C$4), IF(لوحة_القيادة!$C$5="الكل", TRUE, INDEX($V5:$AG5, 1, VALUE(لوحة_القيادة!$C$5))>0)), 1, 0) -> 0 | I5: =IF(H5=1, SUM($H$2:H5), "") -> 0 | J5: 839 | K5: 459 | L5: 899 | M5: 1091 | N5: 507 | O5: 929 | P5: 252 | Q5: 0 | R5: 0 | S5: 0 | T5: 0 | U5: 0 | V5: 17 | W5: 14 | X5: 12 | Y5: 18 | Z5: 17 | AA5: 21 | AB5: 6 | AC5: 0 | AD5: 0 | AE5: 0 | AF5: 0 | AG5: 22 | AH5: 24 | AI5: 23 | AJ5: 19 | AK5: 0 | AL5: 0 | AM5: 17 | AN5: 4 | AO5: 4 | AP5: 2 | AQ5: 3 | AR5: 4 | AS5: 4 | AT5: 1 | AU5: 0 | AV5: 0 | AW5: 0 | AX5: 0 | AY5: 0 | AZ5: 4 | BA5: 4 | BB5: 2 | BC5: 4 | BD5: 4 | BE5: 5 | BF5: 1 | BG5: 0 | BH5: 0 | BI5: 0 | BJ5: 0 | BK5: 0 | BL5: 4 | BM5: 3 | BN5: 4 | BO5: 4 | BP5: 3 | BQ5: 4 | BR5: 1 | BS5: 0 | BT5: 0 | BU5: 0 | BV5: 0 | BW5: 0 | BX5: 3 | BY5: 1 | BZ5: 3 | CA5: 4 | CB5: 2 | CC5: 4 | CD5: 2 | CE5: 0 | CF5: 0 | CG5: 0 | CH5: 0 | CI5: 0 | CJ5: 0 | CK5: 0 | CL5: 0 | CM5: 0 | CN5: 0 | CO5: 0 | CP5: 0 | CQ5: 0 | CR5: 0 | CS5: 0 | CT5: 0 | CU5: 0 | CV5: 0 | CW5: 0 | CX5: 0 | CY5: 0 | CZ5: 0 | DA5: 0 | DB5: 0 | DC5: 0 | DD5: 0 | DE5: 0 | DF5: 0 | DG5: 0 | DH5: 2 | DI5: 2 | DJ5: 1 | DK5: 3 | DL5: 4 | DM5: 4 | DN5: 1 | DO5: 0 | DP5: 0 | DQ5: 0 | DR5: 0 | DS5: 0
A6: عمادة القبول والتسجيل والامتحانات_compressed (1) | B6: احمد ابراهيم محمد دلال | C6: 4940 | D6: 96 | E6: 82.33 | F6: 51.46 | G6: 01، 02، 03، 04، 05، 06، 07 | H6: =IF(AND(OR(لوحة_القيادة!$C$4="الكل", A6=لوحة_القيادة!$C$4), IF(لوحة_القيادة!$C$5="الكل", TRUE, INDEX($V6:$AG6, 1, VALUE(لوحة_القيادة!$C$5))>0)), 1, 0) -> 0 | I6: =IF(H6=1, SUM($H$2:H6), "") -> 0 | J6: 1059 | K6: 1218 | L6: 259 | M6: 770 | N6: 725 | O6: 604 | P6: 305 | Q6: 0 | R6: 0 | S6: 0 | T6: 0 | U6: 0 | V6: 18 | W6: 16 | X6: 5 | Y6: 16 | Z6: 18 | AA6: 17 | AB6: 6 | AC6: 0 | AD6: 0 | AE6: 0 | AF6: 0 | AG6: 21 | AH6: 20 | AI6: 19 | AJ6: 19 | AK6: 0 | AL6: 0 | AM6: 17 | AN6: 4 | AO6: 3 | AP6: 2 | AQ6: 3 | AR6: 5 | AS6: 3 | AT6: 1 | AU6: 0 | AV6: 0 | AW6: 0 | AX6: 0 | AY6: 0 | AZ6: 3 | BA6: 4 | BB6: 1 | BC6: 4 | BD6: 3 | BE6: 4 | BF6: 1 | BG6: 0 | BH6: 0 | BI6: 0 | BJ6: 0 | BK6: 0 | BL6: 4 | BM6: 3 | BN6: 1 | BO6: 3 | BP6: 3 | BQ6: 4 | BR6: 1 | BS6: 0 | BT6: 0 | BU6: 0 | BV6: 0 | BW6: 0 | BX6: 3 | BY6: 3 | BZ6: 1 | CA6: 4 | CB6: 3 | CC6: 3 | CD6: 2 | CE6: 0 | CF6: 0 | CG6: 0 | CH6: 0 | CI6: 0 | CJ6: 0 | CK6: 0 | CL6: 0 | CM6: 0 | CN6: 0 | CO6: 0 | CP6: 0 | CQ6: 0 | CR6: 0 | CS6: 0 | CT6: 0 | CU6: 0 | CV6: 0 | CW6: 0 | CX6: 0 | CY6: 0 | CZ6: 0 | DA6: 0 | DB6: 0 | DC6: 0 | DD6: 0 | DE6: 0 | DF6: 0 | DG6: 0 | DH6: 4 | DI6: 3 | DJ6: 0 | DK6: 2 | DL6: 4 | DM6: 3 | DN6: 1 | DO6: 0 | DP6: 0 | DQ6: 0 | DR6: 0 | DS6: 0
A7: مركز التعليم الرقمي | B7: فؤاد محمد مصطفى صالح | C7: 4026 | D7: 101 | E7: 67.1 | F7: 39.86 | G7: 01، 02، 03، 04، 05، 06، 07 | H7: =IF(AND(OR(لوحة_القيادة!$C$4="الكل", A7=لوحة_القيادة!$C$4), IF(لوحة_القيادة!$C$5="الكل", TRUE, INDEX($V7:$AG7, 1, VALUE(لوحة_القيادة!$C$5))>0)), 1, 0) -> 0 | I7: =IF(H7=1, SUM($H$2:H7), "") -> 0 | J7: 852 | K7: 539 | L7: 470 | M7: 674 | N7: 449 | O7: 721 | P7: 321 | Q7: 0 | R7: 0 | S7: 0 | T7: 0 | U7: 0 | V7: 18 | W7: 18 | X7: 13 | Y7: 15 | Z7: 12 | AA7: 19 | AB7: 6 | AC7: 0 | AD7: 0 | AE7: 0 | AF7: 0 | AG7: 22 | AH7: 25 | AI7: 19 | AJ7: 19 | AK7: 0 | AL7: 0 | AM7: 16 | AN7: 4 | AO7: 4 | AP7: 2 | AQ7: 2 | AR7: 5 | AS7: 4 | AT7: 1 | AU7: 0 | AV7: 0 | AW7: 0 | AX7: 0 | AY7: 0 | AZ7: 4 | BA7: 4 | BB7: 4 | BC7: 4 | BD7: 3 | BE7: 5 | BF7: 1 | BG7: 0 | BH7: 0 | BI7: 0 | BJ7: 0 | BK7: 0 | BL7: 4 | BM7: 4 | BN7: 3 | BO7: 3 | BP7: 1 | BQ7: 3 | BR7: 1 | BS7: 0 | BT7: 0 | BU7: 0 | BV7: 0 | BW7: 0 | BX7: 2 | BY7: 4 | BZ7: 3 | CA7: 3 | CB7: 1 | CC7: 4 | CD7: 2 | CE7: 0 | CF7: 0 | CG7: 0 | CH7: 0 | CI7: 0 | CJ7: 0 | CK7: 0 | CL7: 0 | CM7: 0 | CN7: 0 | CO7: 0 | CP7: 0 | CQ7: 0 | CR7: 0 | CS7: 0 | CT7: 0 | CU7: 0 | CV7: 0 | CW7: 0 | CX7: 0 | CY7: 0 | CZ7: 0 | DA7: 0 | DB7: 0 | DC7: 0 | DD7: 0 | DE7: 0 | DF7: 0 | DG7: 0 | DH7: 4 | DI7: 2 | DJ7: 1 | DK7: 3 | DL7: 2 | DM7: 3 | DN7: 1 | DO7: 0 | DP7: 0 | DQ7: 0 | DR7: 0 | DS7: 0
A8: الإدارة العامة - القدس | B8: باسمة احمد محمد ابوعواد | C8: 3922 | D8: 90 | E8: 65.37 | F8: 43.58 | G8: 01، 02، 03، 04، 05، 06، 07 | H8: =IF(AND(OR(لوحة_القيادة!$C$4="الكل", A8=لوحة_القيادة!$C$4), IF(لوحة_القيادة!$C$5="الكل", TRUE, INDEX($V8:$AG8, 1, VALUE(لوحة_القيادة!$C$5))>0)), 1, 0) -> 0 | I8: =IF(H8=1, SUM($H$2:H8), "") -> 0 | J8: 498 | K8: 730 | L8: 302 | M8: 914 | N8: 547 | O8: 834 | P8: 97 | Q8: 0 | R8: 0 | S8: 0 | T8: 0 | U8: 0 | V8: 10 | W8: 15 | X8: 5 | Y8: 17 | Z8: 18 | AA8: 20 | AB8: 5 | AC8: 0 | AD8: 0 | AE8: 0 | AF8: 0 | AG8: 18 | AH8: 19 | AI8: 18 | AJ8: 18 | AK8: 0 | AL8: 0 | AM8: 17 | AN8: 2 | AO8: 3 | AP8: 0 | AQ8: 3 | AR8: 5 | AS8: 4 | AT8: 1 | AU8: 0 | AV8: 0 | AW8: 0 | AX8: 0 | AY8: 0 | AZ8: 2 | BA8: 3 | BB8: 1 | BC8: 4 | BD8: 4 | BE8: 5 | BF8: 0 | BG8: 0 | BH8: 0 | BI8: 0 | BJ8: 0 | BK8: 0 | BL8: 3 | BM8: 3 | BN8: 2 | BO8: 3 | BP8: 2 | BQ8: 4 | BR8: 1 | BS8: 0 | BT8: 0 | BU8: 0 | BV8: 0 | BW8: 0 | BX8: 1 | BY8: 4 | BZ8: 1 | CA8: 4 | CB8: 3 | CC8: 3 | CD8: 2 | CE8: 0 | CF8: 0 | CG8: 0 | CH8: 0 | CI8: 0 | CJ8: 0 | CK8: 0 | CL8: 0 | CM8: 0 | CN8: 0 | CO8: 0 | CP8: 0 | CQ8: 0 | CR8: 0 | CS8: 0 | CT8: 0 | CU8: 0 | CV8: 0 | CW8: 0 | CX8: 0 | CY8: 0 | CZ8: 0 | DA8: 0 | DB8: 0 | DC8: 0 | DD8: 0 | DE8: 0 | DF8: 0 | DG8: 0 | DH8: 2 | DI8: 2 | DJ8: 1 | DK8: 3 | DL8: 4 | DM8: 4 | DN8: 1 | DO8: 0 | DP8: 0 | DQ8: 0 | DR8: 0 | DS8: 0
A9: فرع جنين | B9: حسن فايز حسن قصراوي | C9: 3511 | D9: 64 | E9: 58.52 | F9: 54.86 | G9: 01، 02، 03، 04، 05، 06، 07 | H9: =IF(AND(OR(لوحة_القيادة!$C$4="الكل", A9=لوحة_القيادة!$C$4), IF(لوحة_القيادة!$C$5="الكل", TRUE, INDEX($V9:$AG9, 1, VALUE(لوحة_القيادة!$C$5))>0)), 1, 0) -> 0 | I9: =IF(H9=1, SUM($H$2:H9), "") -> 0 | J9: 638 | K9: 691 | L9: 117 | M9: 251 | N9: 425 | O9: 1248 | P9: 141 | Q9: 0 | R9: 0 | S9: 0 | T9: 0 | U9: 0 | V9: 15 | W9: 9 | X9: 2 | Y9: 3 | Z9: 11 | AA9: 19 | AB9: 5 | AC9: 0 | AD9: 0 | AE9: 0 | AF9: 0 | AG9: 15 | AH9: 10 | AI9: 12 | AJ9: 12 | AK9: 0 | AL9: 0 | AM9: 15 | AN9: 3 | AO9: 2 | AP9: 1 | AQ9: 0 | AR9: 4 | AS9: 4 | AT9: 1 | AU9: 0 | AV9: 0 | AW9: 0 | AX9: 0 | AY9: 0 | AZ9: 2 | BA9: 1 | BB9: 1 | BC9: 0 | BD9: 1 | BE9: 4 | BF9: 1 | BG9: 0 | BH9: 0 | BI9: 0 | BJ9: 0 | BK9: 0 | BL9: 3 | BM9: 3 | BN9: 0 | BO9: 0 | BP9: 1 | BQ9: 4 | BR9: 1 | BS9: 0 | BT9: 0 | BU9: 0 | BV9: 0 | BW9: 0 | BX9: 3 | BY9: 2 | BZ9: 0 | CA9: 2 | CB9: 1 | CC9: 3 | CD9: 1 | CE9: 0 | CF9: 0 | CG9: 0 | CH9: 0 | CI9: 0 | CJ9: 0 | CK9: 0 | CL9: 0 | CM9: 0 | CN9: 0 | CO9: 0 | CP9: 0 | CQ9: 0 | CR9: 0 | CS9: 0 | CT9: 0 | CU9: 0 | CV9: 0 | CW9: 0 | CX9: 0 | CY9: 0 | CZ9: 0 | DA9: 0 | DB9: 0 | DC9: 0 | DD9: 0 | DE9: 0 | DF9: 0 | DG9: 0 | DH9: 4 | DI9: 1 | DJ9: 0 | DK9: 1 | DL9: 4 | DM9: 4 | DN9: 1 | DO9: 0 | DP9: 0 | DQ9: 0 | DR9: 0 | DS9: 0
A10: عمادة القبول والتسجيل والامتحانات_compressed (1) | B10: احمد حسني حسن سلمان | C10: 3475 | D10: 90 | E10: 57.92 | F10: 38.61 | G10: 01، 02، 03، 04، 05، 06، 07 | H10: =IF(AND(OR(لوحة_القيادة!$C$4="الكل", A10=لوحة_القيادة!$C$4), IF(لوحة_القيادة!$C$5="الكل", TRUE, INDEX($V10:$AG10, 1, VALUE(لوحة_القيادة!$C$5))>0)), 1, 0) -> 0 | I10: =IF(H10=1, SUM($H$2:H10), "") -> 0 | J10: 873 | K10: 570 | L10: 393 | M10: 478 | N10: 503 | O10: 511 | P10: 147 | Q10: 0 | R10: 0 | S10: 0 | T10: 0 | U10: 0 | V10: 17 | W10: 13 | X10: 6 | Y10: 16 | Z10: 15 | AA10: 18 | AB10: 5 | AC10: 0 | AD10: 0 | AE10: 0 | AF10: 0 | AG10: 21 | AH10: 19 | AI10: 19 | AJ10: 16 | AK10: 0 | AL10: 0 | AM10: 15 | AN10: 4 | AO10: 3 | AP10: 1 | AQ10: 3 | AR10: 5 | AS10: 4 | AT10: 1 | AU10: 0 | AV10: 0 | AW10: 0 | AX10: 0 | AY10: 0 | AZ10: 4 | BA10: 2 | BB10: 2 | BC10: 4 | BD10: 2 | BE10: 4 | BF10: 1 | BG10: 0 | BH10: 0 | BI10: 0 | BJ10: 0 | BK10: 0 | BL10: 3 | BM10: 4 | BN10: 2 | BO10: 4 | BP10: 2 | BQ10: 4 | BR10: 0 | BS10: 0 | BT10: 0 | BU10: 0 | BV10: 0 | BW10: 0 | BX10: 3 | BY10: 2 | BZ10: 1 | CA10: 2 | CB10: 3 | CC10: 3 | CD10: 2 | CE10: 0 | CF10: 0 | CG10: 0 | CH10: 0 | CI10: 0 | CJ10: 0 | CK10: 0 | CL10: 0 | CM10: 0 | CN10: 0 | CO10: 0 | CP10: 0 | CQ10: 0 | CR10: 0 | CS10: 0 | CT10: 0 | CU10: 0 | CV10: 0 | CW10: 0 | CX10: 0 | CY10: 0 | CZ10: 0 | DA10: 0 | DB10: 0 | DC10: 0 | DD10: 0 | DE10: 0 | DF10: 0 | DG10: 0 | DH10: 3 | DI10: 2 | DJ10: 0 | DK10: 3 | DL10: 3 | DM10: 3 | DN10: 1 | DO10: 0 | DP10: 0 | DQ10: 0 | DR10: 0 | DS10: 0
A11: عمادة القبول والتسجيل والامتحانات_compressed (1) | B11: ميسون محمد موسى حموده | C11: 3394 | D11: 98 | E11: 56.57 | F11: 34.63 | G11: 01، 02، 03، 04، 05، 06 | H11: =IF(AND(OR(لوحة_القيادة!$C$4="الكل", A11=لوحة_القيادة!$C$4), IF(لوحة_القيادة!$C$5="الكل", TRUE, INDEX($V11:$AG11, 1, VALUE(لوحة_القيادة!$C$5))>0)), 1, 0) -> 0 | I11: =IF(H11=1, SUM($H$2:H11), "") -> 0 | J11: 508 | K11: 632 | L11: 329 | M11: 682 | N11: 559 | O11: 684 | P11: 0 | Q11: 0 | R11: 0 | S11: 0 | T11: 0 | U11: 0 | V11: 17 | W11: 19 | X11: 12 | Y11: 15 | Z11: 16 | AA11: 19 | AB11: 0 | AC11: 0 | AD11: 0 | AE11: 0 | AF11: 0 | AG11: 21 | AH11: 24 | AI11: 14 | AJ11: 18 | AK11: 0 | AL11: 0 | AM11: 21 | AN11: 4 | AO11: 3 | AP11: 2 | AQ11: 3 | AR11: 5 | AS11: 4 | AT11: 0 | AU11: 0 | AV11: 0 | AW11: 0 | AX11: 0 | AY11: 0 | AZ11: 3 | BA11: 4 | BB11: 4 | BC11: 4 | BD11: 4 | BE11: 5 | BF11: 0 | BG11: 0 | BH11: 0 | BI11: 0 | BJ11: 0 | BK11: 0 | BL11: 3 | BM11: 4 | BN11: 2 | BO11: 2 | BP11: 1 | BQ11: 2 | BR11: 0 | BS11: 0 | BT11: 0 | BU11: 0 | BV11: 0 | BW11: 0 | BX11: 3 | BY11: 4 | BZ11: 2 | CA11: 3 | CB11: 2 | CC11: 4 | CD11: 0 | CE11: 0 | CF11: 0 | CG11: 0 | CH11: 0 | CI11: 0 | CJ11: 0 | CK11: 0 | CL11: 0 | CM11: 0 | CN11: 0 | CO11: 0 | CP11: 0 | CQ11: 0 | CR11: 0 | CS11: 0 | CT11: 0 | CU11: 0 | CV11: 0 | CW11: 0 | CX11: 0 | CY11: 0 | CZ11: 0 | DA11: 0 | DB11: 0 | DC11: 0 | DD11: 0 | DE11: 0 | DF11: 0 | DG11: 0 | DH11: 4 | DI11: 4 | DJ11: 2 | DK11: 3 | DL11: 4 | DM11: 4 | DN11: 0 | DO11: 0 | DP11: 0 | DQ11: 0 | DR11: 0 | DS11: 0
A12: فرع طولكرم | B12: جهاد تحسين أحمد طقاطقة | C12: 3356 | D12: 69 | E12: 55.93 | F12: 48.64 | G12: 01، 02، 03، 04، 05، 06، 07 | H12: =IF(AND(OR(لوحة_القيادة!$C$4="الكل", A12=لوحة_القيادة!$C$4), IF(لوحة_القيادة!$C$5="الكل", TRUE, INDEX($V12:$AG12, 1, VALUE(لوحة_القيادة!$C$5))>0)), 1, 0) -> 0 | I12: =IF(H12=1, SUM($H$2:H12), "") -> 0 | J12: 222 | K12: 855 | L12: 914 | M12: 828 | N12: 98 | O12: 160 | P12: 279 | Q12: 0 | R12: 0 | S12: 0 | T12: 0 | U12: 0 | V12: 12 | W12: 18 | X12: 12 | Y12: 17 | Z12: 3 | AA12: 4 | AB12: 3 | AC12: 0 | AD12: 0 | AE12: 0 | AF12: 0 | AG12: 12 | AH12: 15 | AI12: 14 | AJ12: 16 | AK12: 0 | AL12: 0 | AM12: 12 | AN12: 2 | AO12: 3 | AP12: 1 | AQ12: 3 | AR12: 1 | AS12: 1 | AT12: 1 | AU12: 0 | AV12: 0 | AW12: 0 | AX12: 0 | AY12: 0 | AZ12: 3 | BA12: 4 | BB12: 3 | BC12: 3 | BD12: 1 | BE12: 1 | BF12: 0 | BG12: 0 | BH12: 0 | BI12: 0 | BJ12: 0 | BK12: 0 | BL12: 2 | BM12: 4 | BN12: 4 | BO12: 4 | BP12: 0 | BQ12: 0 | BR12: 0 | BS12: 0 | BT12: 0 | BU12: 0 | BV12: 0 | BW12: 0 | BX12: 3 | BY12: 4 | BZ12: 3 | CA12: 4 | CB12: 0 | CC12: 1 | CD12: 1 | CE12: 0 | CF12: 0 | CG12: 0 | CH12: 0 | CI12: 0 | CJ12: 0 | CK12: 0 | CL12: 0 | CM12: 0 | CN12: 0 | CO12: 0 | CP12: 0 | CQ12: 0 | CR12: 0 | CS12: 0 | CT12: 0 | CU12: 0 | CV12: 0 | CW12: 0 | CX12: 0 | CY12: 0 | CZ12: 0 | DA12: 0 | DB12: 0 | DC12: 0 | DD12: 0 | DE12: 0 | DF12: 0 | DG12: 0 | DH12: 2 | DI12: 3 | DJ12: 1 | DK12: 3 | DL12: 1 | DM12: 1 | DN12: 1 | DO12: 0 | DP12: 0 | DQ12: 0 | DR12: 0 | DS12: 0
A13: عمادة الدراسات العليا والبحث العلمي_compressed (1) | B13: كميل غالب محمد زيد | C13: 3355 | D13: 91 | E13: 55.92 | F13: 36.87 | G13: 01، 02، 03، 04، 05، 06، 07 | H13: =IF(AND(OR(لوحة_القيادة!$C$4="الكل", A13=لوحة_القيادة!$C$4), IF(لوحة_القيادة!$C$5="الكل", TRUE, INDEX($V13:$AG13, 1, VALUE(لوحة_القيادة!$C$5))>0)), 1, 0) -> 0 | I13: =IF(H13=1, SUM($H$2:H13), "") -> 0 | J13: 843 | K13: 597 | L13: 378 | M13: 500 | N13: 651 | O13: 359 | P13: 27 | Q13: 0 | R13: 0 | S13: 0 | T13: 0 | U13: 0 | V13: 18 | W13: 18 | X13: 9 | Y13: 14 | Z13: 14 | AA13: 14 | AB13: 4 | AC13: 0 | AD13: 0 | AE13: 0 | AF13: 0 | AG13: 17 | AH13: 22 | AI13: 20 | AJ13: 21 | AK13: 0 | AL13: 0 | AM13: 11 | AN13: 4 | AO13: 4 | AP13: 0 | AQ13: 2 | AR13: 3 | AS13: 3 | AT13: 1 | AU13: 0 | AV13: 0 | AW13: 0 | AX13: 0 | AY13: 0 | AZ13: 4 | BA13: 4 | BB13: 3 | BC13: 3 | BD13: 3 | BE13: 4 | BF13: 1 | BG13: 0 | BH13: 0 | BI13: 0 | BJ13: 0 | BK13: 0 | BL13: 4 | BM13: 3 | BN13: 3 | BO13: 4 | BP13: 2 | BQ13: 3 | BR13: 1 | BS13: 0 | BT13: 0 | BU13: 0 | BV13: 0 | BW13: 0 | BX13: 3 | BY13: 4 | BZ13: 3 | CA13: 4 | CB13: 3 | CC13: 3 | CD13: 1 | CE13: 0 | CF13: 0 | CG13: 0 | CH13: 0 | CI13: 0 | CJ13: 0 | CK13: 0 | CL13: 0 | CM13: 0 | CN13: 0 | CO13: 0 | CP13: 0 | CQ13: 0 | CR13: 0 | CS13: 0 | CT13: 0 | CU13: 0 | CV13: 0 | CW13: 0 | CX13: 0 | CY13: 0 | CZ13: 0 | DA13: 0 | DB13: 0 | DC13: 0 | DD13: 0 | DE13: 0 | DF13: 0 | DG13: 0 | DH13: 3 | DI13: 3 | DJ13: 0 | DK13: 1 | DL13: 3 | DM13: 1 | DN13: 0 | DO13: 0 | DP13: 0 | DQ13: 0 | DR13: 0 | DS13: 0
... A455: فرع طولكرم | B455: سعادة خالد محمد ابو شملة | C455: 1 | D455: 1 | E455: 0.02 | F455: 1 | G455: 01 | H455: =IF(AND(OR(لوحة_القيادة!$C$4="الكل", A455=لوحة_القيادة!$C$4), IF(لوحة_القيادة!$C$5="الكل", TRUE, INDEX($V455:$AG455, 1, VALUE(لوحة_القيادة!$C$5))>0)), 1, 0) -> 0 | I455: =IF(H455=1, SUM($H$2:H455), "") -> 0 | J455: 1 | K455: 0 | L455: 0 | M455: 0 | N455: 0 | O455: 0 | P455: 0 | Q455: 0 | R455: 0 | S455: 0 | T455: 0 | U455: 0 | V455: 1 | W455: 0 | X455: 0 | Y455: 0 | Z455: 0 | AA455: 0 | AB455: 0 | AC455: 0 | AD455: 0 | AE455: 0 | AF455: 0 | AG455: 0 | AH455: 1 | AI455: 0 | AJ455: 0 | AK455: 0 | AL455: 0 | AM455: 0 | AN455: 0 | AO455: 0 | AP455: 0 | AQ455: 0 | AR455: 0 | AS455: 0 | AT455: 0 | AU455: 0 | AV455: 0 | AW455: 0 | AX455: 0 | AY455: 0 | AZ455: 1 | BA455: 0 | BB455: 0 | BC455: 0 | BD455: 0 | BE455: 0 | BF455: 0 | BG455: 0 | BH455: 0 | BI455: 0 | BJ455: 0 | BK455: 0 | BL455: 0 | BM455: 0 | BN455: 0 | BO455: 0 | BP455: 0 | BQ455: 0 | BR455: 0 | BS455: 0 | BT455: 0 | BU455: 0 | BV455: 0 | BW455: 0 | BX455: 0 | BY455: 0 | BZ455: 0 | CA455: 0 | CB455: 0 | CC455: 0 | CD455: 0 | CE455: 0 | CF455: 0 | CG455: 0 | CH455: 0 | CI455: 0 | CJ455: 0 | CK455: 0 | CL455: 0 | CM455: 0 | CN455: 0 | CO455: 0 | CP455: 0 | CQ455: 0 | CR455: 0 | CS455: 0 | CT455: 0 | CU455: 0 | CV455: 0 | CW455: 0 | CX455: 0 | CY455: 0 | CZ455: 0 | DA455: 0 | DB455: 0 | DC455: 0 | DD455: 0 | DE455: 0 | DF455: 0 | DG455: 0 | DH455: 0 | DI455: 0 | DJ455: 0 | DK455: 0 | DL455: 0 | DM455: 0 | DN455: 0 | DO455: 0 | DP455: 0 | DQ455: 0 | DR455: 0 | DS455: 0

Sheet ملخص_الفروع
A1: التقرير الشامل لأداء الفروع
A4: الفرع | B4: إجمالي الدقائق | C4: إجمالي الساعات | D4: متوسط دقائق التأخير | E4: إجمالي الموظفين المتأخرين | F4: الموظف الأكثر تأخيراً | G4: إجمالي حالات التأخير | H4: اليوم الأكثر تكراراً
A5: فرع رام الله والبيرة | B5: 35997 | C5: 599.95 | D5: 25.92 | E5: 44 | F5: عز الدين محمد مصطفى أبو نزهة (7969 دقيقة) | G5: 1389 | H5: الاثنين
A6: فرع جنين | B6: 23001 | C6: 383.35 | D6: 33.87 | E6: 45 | F6: حسن فايز حسن قصراوي (3511 دقيقة) | G6: 679 | H6: الاثنين
A7: الإدارة العامة - القدس | B7: 18315 | C7: 305.25 | D7: 24.1 | E7: 20 | F7: رامي نجيب محمود خليل (5561 دقيقة) | G7: 760 | H7: الاثنين
A8: عمادة القبول والتسجيل والامتحانات_compressed (1) | B8: 18213 | C8: 303.55 | D8: 23.56 | E8: 16 | F8: احمد ابراهيم محمد دلال (4940 دقيقة) | G8: 773 | H8: الاثنين
A9: فرع طولكرم | B9: 16025 | C9: 267.08 | D9: 24.32 | E9: 44 | F9: جهاد تحسين أحمد طقاطقة (3356 دقيقة) | G9: 659 | H9: الأربعاء
A10: مركز التعليم الرقمي | B10: 15562 | C10: 259.37 | D10: 28.35 | E10: 9 | F10: ابراهيم محمد ابراهيم ابو تركي (4976 دقيقة) | G10: 549 | H10: الاثنين
A11: مركز تكنولوجيا المعلومات | B11: 14471 | C11: 241.18 | D11: 23.61 | E11: 19 | F11: محمد سليمان ابراهيم الخليل (2950 دقيقة) | G11: 613 | H11: الاثنين
A12: عمادة الدراسات العليا والبحث العلمي_compressed (1) | B12: 13549 | C12: 225.82 | D12: 18.82 | E12: 18 | F12: كميل غالب محمد زيد (3355 دقيقة) | G12: 720 | H12: الاثنين
A13: العلاقات العامة | B13: 12851 | C13: 214.18 | D13: 26.28 | E13: 8 | F13: يوسف ابراهيم يوسف الرفاعي (3243 دقيقة) | G13: 489 | H13: الثلاثاء
A14: فرع نابلس | B14: 7731 | C14: 128.85 | D14: 19.62 | E14: 47 | F14: بلال محمد حسين مشارقة (1104 دقيقة) | G14: 394 | H14: الأحد
A15: فرع الخليل | B15: 5711 | C15: 95.18 | D15: 27.59 | E15: 26 | F15: نادر سليمان عوض أبو حسين (1855 دقيقة) | G15: 207 | H15: الاثنين
A16: فرع بيت لحم | B16: 5057 | C16: 84.28 | D16: 13.7 | E16: 26 | F16: رنا انطون حنا مصلح (1224 دقيقة) | G16: 369 | H16: الثلاثاء
... A26: فـــرع يــطـــا | B26: 443 | C26: 7.38 | D26: 7.26 | E26: 10 | F26: عماد أحمد عيسى أبو حسان (156 دقيقة) | G26: 61 | H26: الأحد

Sheet لوحة_القيادة
B2: لوحة القيادة التفاعلية للموظفين المتأخرين
B4: تصفية حسب الفرع: | C4: الكل
B5: تصفية حسب الشهر: | C5: الكل
B7: إجمالي الموظفين المتأخرين | D7: إجمالي حالات التأخير | F7: إجمالي الدقائق | H7: إجمالي الساعات | J7: اليوم الأكثر تكراراً
B8: =MAX(البيانات_الأساسية!I:I) -> 0 | D8: =IF($C$5="الكل", SUMIFS(البيانات_الأساسية!D:D, البيانات_الأساسية!H:H, 1), SUMIFS(INDEX(البيانات_الأساسية!$V:$AG, 0, VALUE($C$5)), البيانات_الأساسية!H:H, 1)) -> 0 | F8: =IF($C$5="الكل", SUMIFS(البيانات_الأساسية!C:C, البيانات_الأساسية!H:H, 1), SUMIFS(INDEX(البيانات_الأساسية!$J:$U, 0, VALUE($C$5)), البيانات_الأساسية!H:H, 1)) -> 0 | H8: =ROUND(F8/60, 2) -> 0 | J8: =IF(MAX(AA100:AA106)=0, "لا يوجد", INDEX(Z100:Z106, MATCH(MAX(AA100:AA106), AA100:AA106, 0))) -> 0
B11: جدول التفاصيل للموظفين
B13: الترتيب | C13: الفرع | D13: اسم الموظف | E13: عدد التأخيرات | F13: إجمالي الدقائق | G13: إجمالي الساعات | H13: متوسط التأخير | I13: الأشهر المسجلة
B14: =IF(C14="","", 1) -> 0 | C14: =IFERROR(INDEX(البيانات_الأساسية!A:A, MATCH(1, البيانات_الأساسية!$I:$I, 0)), "") -> 0 | D14: =IFERROR(INDEX(البيانات_الأساسية!B:B, MATCH(1, البيانات_الأساسية!$I:$I, 0)), "") -> 0 | E14: =IFERROR(IF($C$5="الكل", INDEX(البيانات_الأساسية!D:D, MATCH(1, البيانات_الأساسية!$I:$I, 0)), INDEX(البيانات_الأساسية!$V:$AG, MATCH(1, البيانات_الأساسية!$I:$I, 0), VALUE($C$5))), "") -> 0 | F14: =IFERROR(IF($C$5="الكل", INDEX(البيانات_الأساسية!C:C, MATCH(1, البيانات_الأساسية!$I:$I, 0)), INDEX(البيانات_الأساسية!$J:$U, MATCH(1, البيانات_الأساسية!$I:$I, 0), VALUE($C$5))), "") -> 0 | G14: =IFERROR(ROUND(F14/60, 2), "") -> 0 | H14: =IFERROR(ROUND(F14/E14, 2), "") -> 0 | I14: =IFERROR(IF($C$5="الكل", INDEX(البيانات_الأساسية!G:G, MATCH(1, البيانات_الأساسية!$I:$I, 0)), $C$5), "") -> 0
B15: =IF(C15="","", 2) -> 0 | C15: =IFERROR(INDEX(البيانات_الأساسية!A:A, MATCH(2, البيانات_الأساسية!$I:$I, 0)), "") -> 0 | D15: =IFERROR(INDEX(البيانات_الأساسية!B:B, MATCH(2, البيانات_الأساسية!$I:$I, 0)), "") -> 0 | E15: =IFERROR(IF($C$5="الكل", INDEX(البيانات_الأساسية!D:D, MATCH(2, البيانات_الأساسية!$I:$I, 0)), INDEX(البيانات_الأساسية!$V:$AG, MATCH(2, البيانات_الأساسية!$I:$I, 0), VALUE($C$5))), "") -> 0 | F15: =IFERROR(IF($C$5="الكل", INDEX(البيانات_الأساسية!C:C, MATCH(2, البيانات_الأساسية!$I:$I, 0)), INDEX(البيانات_الأساسية!$J:$U, MATCH(2, البيانات_الأساسية!$I:$I, 0), VALUE($C$5))), "") -> 0 | G15: =IFERROR(ROUND(F15/60, 2), "") -> 0 | H15: =IFERROR(ROUND(F15/E15, 2), "") -> 0 | I15: =IFERROR(IF($C$5="الكل", INDEX(البيانات_الأساسية!G:G, MATCH(2, البيانات_الأساسية!$I:$I, 0)), $C$5), "") -> 0
B16: =IF(C16="","", 3) -> 0 | C16: =IFERROR(INDEX(البيانات_الأساسية!A:A, MATCH(3, البيانات_الأساسية!$I:$I, 0)), "") -> 0 | D16: =IFERROR(INDEX(البيانات_الأساسية!B:B, MATCH(3, البيانات_الأساسية!$I:$I, 0)), "") -> 0 | E16: =IFERROR(IF($C$5="الكل", INDEX(البيانات_الأساسية!D:D, MATCH(3, البيانات_الأساسية!$I:$I, 0)), INDEX(البيانات_الأساسية!$V:$AG, MATCH(3, البيانات_الأساسية!$I:$I, 0), VALUE($C$5))), "") -> 0 | F16: =IFERROR(IF($C$5="الكل", INDEX(البيانات_الأساسية!C:C, MATCH(3, البيانات_الأساسية!$I:$I, 0)), INDEX(البيانات_الأساسية!$J:$U, MATCH(3, البيانات_الأساسية!$I:$I, 0), VALUE($C$5))), "") -> 0 | G16: =IFERROR(ROUND(F16/60, 2), "") -> 0 | H16: =IFERROR(ROUND(F16/E16, 2), "") -> 0 | I16: =IFERROR(IF($C$5="الكل", INDEX(البيانات_الأساسية!G:G, MATCH(3, البيانات_الأساسية!$I:$I, 0)), $C$5), "") -> 0
B17: =IF(C17="","", 4) -> 0 | C17: =IFERROR(INDEX(البيانات_الأساسية!A:A, MATCH(4, البيانات_الأساسية!$I:$I, 0)), "") -> 0 | D17: =IFERROR(INDEX(البيانات_الأساسية!B:B, MATCH(4, البيانات_الأساسية!$I:$I, 0)), "") -> 0 | E17: =IFERROR(IF($C$5="الكل", INDEX(البيانات_الأساسية!D:D, MATCH(4, البيانات_الأساسية!$I:$I, 0)), INDEX(البيانات_الأساسية!$V:$AG, MATCH(4, البيانات_الأساسية!$I:$I, 0), VALUE($C$5))), "") -> 0 | F17: =IFERROR(IF($C$5="الكل", INDEX(البيانات_الأساسية!C:C, MATCH(4, البيانات_الأساسية!$I:$I, 0)), INDEX(البيانات_الأساسية!$J:$U, MATCH(4, البيانات_الأساسية!$I:$I, 0), VALUE($C$5))), "") -> 0 | G17: =IFERROR(ROUND(F17/60, 2), "") -> 0 | H17: =IFERROR(ROUND(F17/E17, 2), "") -> 0 | I17: =IFERROR(IF($C$5="الكل", INDEX(البيانات_الأساسية!G:G, MATCH(4, البيانات_الأساسية!$I:$I, 0)), $C$5), "") -> 0
B18: =IF(C18="","", 5) -> 0 | C18: =IFERROR(INDEX(البيانات_الأساسية!A:A, MATCH(5, البيانات_الأساسية!$I:$I, 0)), "") -> 0 | D18: =IFERROR(INDEX(البيانات_الأساسية!B:B, MATCH(5, البيانات_الأساسية!$I:$I, 0)), "") -> 0 | E18: =IFERROR(IF($C$5="الكل", INDEX(البيانات_الأساسية!D:D, MATCH(5, البيانات_الأساسية!$I:$I, 0)), INDEX(البيانات_الأساسية!$V:$AG, MATCH(5, البيانات_الأساسية!$I:$I, 0), VALUE($C$5))), "") -> 0 | F18: =IFERROR(IF($C$5="الكل", INDEX(البيانات_الأساسية!C:C, MATCH(5, البيانات_الأساسية!$I:$I, 0)), INDEX(البيانات_الأساسية!$J:$U, MATCH(5, البيانات_الأساسية!$I:$I, 0), VALUE($C$5))), "") -> 0 | G18: =IFERROR(ROUND(F18/60, 2), "") -> 0 | H18: =IFERROR(ROUND(F18/E18, 2), "") -> 0 | I18: =IFERROR(IF($C$5="الكل", INDEX(البيانات_الأساسية!G:G, MATCH(5, البيانات_الأساسية!$I:$I, 0)), $C$5), "") -> 0
B19: =IF(C19="","", 6) -> 0 | C19: =IFERROR(INDEX(البيانات_الأساسية!A:A, MATCH(6, البيانات_الأساسية!$I:$I, 0)), "") -> 0 | D19: =IFERROR(INDEX(البيانات_الأساسية!B:B, MATCH(6, البيانات_الأساسية!$I:$I, 0)), "") -> 0 | E19: =IFERROR(IF($C$5="الكل", INDEX(البيانات_الأساسية!D:D, MATCH(6, البيانات_الأساسية!$I:$I, 0)), INDEX(البيانات_الأساسية!$V:$AG, MATCH(6, البيانات_الأساسية!$I:$I, 0), VALUE($C$5))), "") -> 0 | F19: =IFERROR(IF($C$5="الكل", INDEX(البيانات_الأساسية!C:C, MATCH(6, البيانات_الأساسية!$I:$I, 0)), INDEX(البيانات_الأساسية!$J:$U, MATCH(6, البيانات_الأساسية!$I:$I, 0), VALUE($C$5))), "") -> 0 | G19: =IFERROR(ROUND(F19/60, 2), "") -> 0 | H19: =IFERROR(ROUND(F19/E19, 2), "") -> 0 | I19: =IFERROR(IF($C$5="الكل", INDEX(البيانات_الأساسية!G:G, MATCH(6, البيانات_الأساسية!$I:$I, 0)), $C$5), "") -> 0
B20: =IF(C20="","", 7) -> 0 | C20: =IFERROR(INDEX(البيانات_الأساسية!A:A, MATCH(7, البيانات_الأساسية!$I:$I, 0)), "") -> 0 | D20: =IFERROR(INDEX(البيانات_الأساسية!B:B, MATCH(7, البيانات_الأساسية!$I:$I, 0)), "") -> 0 | E20: =IFERROR(IF($C$5="الكل", INDEX(البيانات_الأساسية!D:D, MATCH(7, البيانات_الأساسية!$I:$I, 0)), INDEX(البيانات_الأساسية!$V:$AG, MATCH(7, البيانات_الأساسية!$I:$I, 0), VALUE($C$5))), "") -> 0 | F20: =IFERROR(IF($C$5="الكل", INDEX(البيانات_الأساسية!C:C, MATCH(7, البيانات_الأساسية!$I:$I, 0)), INDEX(البيانات_الأساسية!$J:$U, MATCH(7, البيانات_الأساسية!$I:$I, 0), VALUE($C$5))), "") -> 0 | G20: =IFERROR(ROUND(F20/60, 2), "") -> 0 | H20: =IFERROR(ROUND(F20/E20, 2), "") -> 0 | I20: =IFERROR(IF($C$5="الكل", INDEX(البيانات_الأساسية!G:G, MATCH(7, البيانات_الأساسية!$I:$I, 0)), $C$5), "") -> 0
B21: =IF(C21="","", 8) -> 0 | C21: =IFERROR(INDEX(البيانات_الأساسية!A:A, MATCH(8, البيانات_الأساسية!$I:$I, 0)), "") -> 0 | D21: =IFERROR(INDEX(البيانات_الأساسية!B:B, MATCH(8, البيانات_الأساسية!$I:$I, 0)), "") -> 0 | E21: =IFERROR(IF($C$5="الكل", INDEX(البيانات_الأساسية!D:D, MATCH(8, البيانات_الأساسية!$I:$I, 0)), INDEX(البيانات_الأساسية!$V:$AG, MATCH(8, البيانات_الأساسية!$I:$I, 0), VALUE($C$5))), "") -> 0 | F21: =IFERROR(IF($C$5="الكل", INDEX(البيانات_الأساسية!C:C, MATCH(8, البيانات_الأساسية!$I:$I, 0)), INDEX(البيانات_الأساسية!$J:$U, MATCH(8, البيانات_الأساسية!$I:$I, 0), VALUE($C$5))), "") -> 0 | G21: =IFERROR(ROUND(F21/60, 2), "") -> 0 | H21: =IFERROR(ROUND(F21/E21, 2), "") -> 0 | I21: =IFERROR(IF($C$5="الكل", INDEX(البيانات_الأساسية!G:G, MATCH(8, البيانات_الأساسية!$I:$I, 0)), $C$5), "") -> 0
B22: =IF(C22="","", 9) -> 0 | C22: =IFERROR(INDEX(البيانات_الأساسية!A:A, MATCH(9, البيانات_الأساسية!$I:$I, 0)), "") -> 0 | D22: =IFERROR(INDEX(البيانات_الأساسية!B:B, MATCH(9, البيانات_الأساسية!$I:$I, 0)), "") -> 0 | E22: =IFERROR(IF($C$5="الكل", INDEX(البيانات_الأساسية!D:D, MATCH(9, البيانات_الأساسية!$I:$I, 0)), INDEX(البيانات_الأساسية!$V:$AG, MATCH(9, البيانات_الأساسية!$I:$I, 0), VALUE($C$5))), "") -> 0 | F22: =IFERROR(IF($C$5="الكل", INDEX(البيانات_الأساسية!C:C, MATCH(9, البيانات_الأساسية!$I:$I, 0)), INDEX(البيانات_الأساسية!$J:$U, MATCH(9, البيانات_الأساسية!$I:$I, 0), VALUE($C$5))), "") -> 0 | G22: =IFERROR(ROUND(F22/60, 2), "") -> 0 | H22: =IFERROR(ROUND(F22/E22, 2), "") -> 0 | I22: =IFERROR(IF($C$5="الكل", INDEX(البيانات_الأساسية!G:G, MATCH(9, البيانات_الأساسية!$I:$I, 0)), $C$5), "") -> 0
B23: =IF(C23="","", 10) -> 0 | C23: =IFERROR(INDEX(البيانات_الأساسية!A:A, MATCH(10, البيانات_الأساسية!$I:$I, 0)), "") -> 0 | D23: =IFERROR(INDEX(البيانات_الأساسية!B:B, MATCH(10, البيانات_الأساسية!$I:$I, 0)), "") -> 0 | E23: =IFERROR(IF($C$5="الكل", INDEX(البيانات_الأساسية!D:D, MATCH(10, البيانات_الأساسية!$I:$I, 0)), INDEX(البيانات_الأساسية!$V:$AG, MATCH(10, البيانات_الأساسية!$I:$I, 0), VALUE($C$5))), "") -> 0 | F23: =IFERROR(IF($C$5="الكل", INDEX(البيانات_الأساسية!C:C, MATCH(10, البيانات_الأساسية!$I:$I, 0)), INDEX(البيانات_الأساسية!$J:$U, MATCH(10, البيانات_الأساسية!$I:$I, 0), VALUE($C$5))), "") -> 0 | G23: =IFERROR(ROUND(F23/60, 2), "") -> 0 | H23: =IFERROR(ROUND(F23/E23, 2), "") -> 0 | I23: =IFERROR(IF($C$5="الكل", INDEX(البيانات_الأساسية!G:G, MATCH(10, البيانات_الأساسية!$I:$I, 0)), $C$5), "") -> 0
B24: =IF(C24="","", 11) -> 0 | C24: =IFERROR(INDEX(البيانات_الأساسية!A:A, MATCH(11, البيانات_الأساسية!$I:$I, 0)), "") -> 0 | D24: =IFERROR(INDEX(البيانات_الأساسية!B:B, MATCH(11, البيانات_الأساسية!$I:$I, 0)), "") -> 0 | E24: =IFERROR(IF($C$5="الكل", INDEX(البيانات_الأساسية!D:D, MATCH(11, البيانات_الأساسية!$I:$I, 0)), INDEX(البيانات_الأساسية!$V:$AG, MATCH(11, البيانات_الأساسية!$I:$I, 0), VALUE($C$5))), "") -> 0 | F24: =IFERROR(IF($C$5="الكل", INDEX(البيانات_الأساسية!C:C, MATCH(11, البيانات_الأساسية!$I:$I, 0)), INDEX(البيانات_الأساسية!$J:$U, MATCH(11, البيانات_الأساسية!$I:$I, 0), VALUE($C$5))), "") -> 0 | G24: =IFERROR(ROUND(F24/60, 2), "") -> 0 | H24: =IFERROR(ROUND(F24/E24, 2), "") -> 0 | I24: =IFERROR(IF($C$5="الكل", INDEX(البيانات_الأساسية!G:G, MATCH(11, البيانات_الأساسية!$I:$I, 0)), $C$5), "") -> 0
B25: =IF(C25="","", 12) -> 0 | C25: =IFERROR(INDEX(البيانات_الأساسية!A:A, MATCH(12, البيانات_الأساسية!$I:$I, 0)), "") -> 0 | D25: =IFERROR(INDEX(البيانات_الأساسية!B:B, MATCH(12, البيانات_الأساسية!$I:$I, 0)), "") -> 0 | E25: =IFERROR(IF($C$5="الكل", INDEX(البيانات_الأساسية!D:D, MATCH(12, البيانات_الأساسية!$I:$I, 0)), INDEX(البيانات_الأساسية!$V:$AG, MATCH(12, البيانات_الأساسية!$I:$I, 0), VALUE($C$5))), "") -> 0 | F25: =IFERROR(IF($C$5="الكل", INDEX(البيانات_الأساسية!C:C, MATCH(12, البيانات_الأساسية!$I:$I, 0)), INDEX(البيانات_الأساسية!$J:$U, MATCH(12, البيانات_الأساسية!$I:$I, 0), VALUE($C$5))), "") -> 0 | G25: =IFERROR(ROUND(F25/60, 2), "") -> 0 | H25: =IFERROR(ROUND(F25/E25, 2), "") -> 0 | I25: =IFERROR(IF($C$5="الكل", INDEX(البيانات_الأساسية!G:G, MATCH(12, البيانات_الأساسية!$I:$I, 0)), $C$5), "") -> 0
B26: =IF(C26="","", 13) -> 0 | C26: =IFERROR(INDEX(البيانات_الأساسية!A:A, MATCH(13, البيانات_الأساسية!$I:$I, 0)), "") -> 0 | D26: =IFERROR(INDEX(البيانات_الأساسية!B:B, MATCH(13, البيانات_الأساسية!$I:$I, 0)), "") -> 0 | E26: =IFERROR(IF($C$5="الكل", INDEX(البيانات_الأساسية!D:D, MATCH(13, البيانات_الأساسية!$I:$I, 0)), INDEX(البيانات_الأساسية!$V:$AG, MATCH(13, البيانات_الأساسية!$I:$I, 0), VALUE($C$5))), "") -> 0 | F26: =IFERROR(IF($C$5="الكل", INDEX(البيانات_الأساسية!C:C, MATCH(13, البيانات_الأساسية!$I:$I, 0)), INDEX(البيانات_الأساسية!$J:$U, MATCH(13, البيانات_الأساسية!$I:$I, 0), VALUE($C$5))), "") -> 0 | G26: =IFERROR(ROUND(F26/60, 2), "") -> 0 | H26: =IFERROR(ROUND(F26/E26, 2), "") -> 0 | I26: =IFERROR(IF($C$5="الكل", INDEX(البيانات_الأساسية!G:G, MATCH(13, البيانات_الأساسية!$I:$I, 0)), $C$5), "") -> 0
B27: =IF(C27="","", 14) -> 0 | C27: =IFERROR(INDEX(البيانات_الأساسية!A:A, MATCH(14, البيانات_الأساسية!$I:$I, 0)), "") -> 0 | D27: =IFERROR(INDEX(البيانات_الأساسية!B:B, MATCH(14, البيانات_الأساسية!$I:$I, 0)), "") -> 0 | E27: =IFERROR(IF($C$5="الكل", INDEX(البيانات_الأساسية!D:D, MATCH(14, البيانات_الأساسية!$I:$I, 0)), INDEX(البيانات_الأساسية!$V:$AG, MATCH(14, البيانات_الأساسية!$I:$I, 0), VALUE($C$5))), "") -> 0 | F27: =IFERROR(IF($C$5="الكل", INDEX(البيانات_الأساسية!C:C, MATCH(14, البيانات_الأساسية!$I:$I, 0)), INDEX(البيانات_الأساسية!$J:$U, MATCH(14, البيانات_الأساسية!$I:$I, 0), VALUE($C$5))), "") -> 0 | G27: =IFERROR(ROUND(F27/60, 2), "") -> 0 | H27: =IFERROR(ROUND(F27/E27, 2), "") -> 0 | I27: =IFERROR(IF($C$5="الكل", INDEX(البيانات_الأساسية!G:G, MATCH(14, البيانات_الأساسية!$I:$I, 0)), $C$5), "") -> 0
B28: =IF(C28="","", 15) -> 0 | C28: =IFERROR(INDEX(البيانات_الأساسية!A:A, MATCH(15, البيانات_الأساسية!$I:$I, 0)), "") -> 0 | D28: =IFERROR(INDEX(البيانات_الأساسية!B:B, MATCH(15, البيانات_الأساسية!$I:$I, 0)), "") -> 0 | E28: =IFERROR(IF($C$5="الكل", INDEX(البيانات_الأساسية!D:D, MATCH(15, البيانات_الأساسية!$I:$I, 0)), INDEX(البيانات_الأساسية!$V:$AG, MATCH(15, البيانات_الأساسية!$I:$I, 0), VALUE($C$5))), "") -> 0 | F28: =IFERROR(IF($C$5="الكل", INDEX(البيانات_الأساسية!C:C, MATCH(15, البيانات_الأساسية!$I:$I, 0)), INDEX(البيانات_الأساسية!$J:$U, MATCH(15, البيانات_الأساسية!$I:$I, 0), VALUE($C$5))), "") -> 0 | G28: =IFERROR(ROUND(F28/60, 2), "") -> 0 | H28: =IFERROR(ROUND(F28/E28, 2), "") -> 0 | I28: =IFERROR(IF($C$5="الكل", INDEX(البيانات_الأساسية!G:G, MATCH(15, البيانات_الأساسية!$I:$I, 0)), $C$5), "") -> 0
B29: =IF(C29="","", 16) -> 0 | C29: =IFERROR(INDEX(البيانات_الأساسية!A:A, MATCH(16, البيانات_الأساسية!$I:$I, 0)), "") -> 0 | D29: =IFERROR(INDEX(البيانات_الأساسية!B:B, MATCH(16, البيانات_الأساسية!$I:$I, 0)), "") -> 0 | E29: =IFERROR(IF($C$5="الكل", INDEX(البيانات_الأساسية!D:D, MATCH(16, البيانات_الأساسية!$I:$I, 0)), INDEX(البيانات_الأساسية!$V:$AG, MATCH(16, البيانات_الأساسية!$I:$I, 0), VALUE($C$5))), "") -> 0 | F29: =IFERROR(IF($C$5="الكل", INDEX(البيانات_الأساسية!C:C, MATCH(16, البيانات_الأساسية!$I:$I, 0)), INDEX(البيانات_الأساسية!$J:$U, MATCH(16, البيانات_الأساسية!$I:$I, 0), VALUE($C$5))), "") -> 0 | G29: =IFERROR(ROUND(F29/60, 2), "") -> 0 | H29: =IFERROR(ROUND(F29/E29, 2), "") -> 0 | I29: =IFERROR(IF($C$5="الكل", INDEX(البيانات_الأساسية!G:G, MATCH(16, البيانات_الأساسية!$I:$I, 0)), $C$5), "") -> 0
B30: =IF(C30="","", 17) -> 0 | C30: =IFERROR(INDEX(البيانات_الأساسية!A:A, MATCH(17, البيانات_الأساسية!$I:$I, 0)), "") -> 0 | D30: =IFERROR(INDEX(البيانات_الأساسية!B:B, MATCH(17, البيانات_الأساسية!$I:$I, 0)), "") -> 0 | E30: =IFERROR(IF($C$5="الكل", INDEX(البيانات_الأساسية!D:D, MATCH(17, البيانات_الأساسية!$I:$I, 0)), INDEX(البيانات_الأساسية!$V:$AG, MATCH(17, البيانات_الأساسية!$I:$I, 0), VALUE($C$5))), "") -> 0 | F30: =IFERROR(IF($C$5="الكل", INDEX(البيانات_الأساسية!C:C, MATCH(17, البيانات_الأساسية!$I:$I, 0)), INDEX(البيانات_الأساسية!$J:$U, MATCH(17, البيانات_الأساسية!$I:$I, 0), VALUE($C$5))), "") -> 0 | G30: =IFERROR(ROUND(F30/60, 2), "") -> 0 | H30: =IFERROR(ROUND(F30/E30, 2), "") -> 0 | I30: =IFERROR(IF($C$5="الكل", INDEX(البيانات_الأساسية!G:G, MATCH(17, البيانات_الأساسية!$I:$I, 0)), $C$5), "") -> 0
B31: =IF(C31="","", 18) -> 0 | C31: =IFERROR(INDEX(البيانات_الأساسية!A:A, MATCH(18, البيانات_الأساسية!$I:$I, 0)), "") -> 0 | D31: =IFERROR(INDEX(البيانات_الأساسية!B:B, MATCH(18, البيانات_الأساسية!$I:$I, 0)), "") -> 0 | E31: =IFERROR(IF($C$5="الكل", INDEX(البيانات_الأساسية!D:D, MATCH(18, البيانات_الأساسية!$I:$I, 0)), INDEX(البيانات_الأساسية!$V:$AG, MATCH(18, البيانات_الأساسية!$I:$I, 0), VALUE($C$5))), "") -> 0 | F31: =IFERROR(IF($C$5="الكل", INDEX(البيانات_الأساسية!C:C, MATCH(18, البيانات_الأساسية!$I:$I, 0)), INDEX(البيانات_الأساسية!$J:$U, MATCH(18, البيانات_الأساسية!$I:$I, 0), VALUE($C$5))), "") -> 0 | G31: =IFERROR(ROUND(F31/60, 2), "") -> 0 | H31: =IFERROR(ROUND(F31/E31, 2), "") -> 0 | I31: =IFERROR(IF($C$5="الكل", INDEX(البيانات_الأساسية!G:G, MATCH(18, البيانات_الأساسية!$I:$I, 0)), $C$5), "") -> 0
B32: =IF(C32="","", 19) -> 0 | C32: =IFERROR(INDEX(البيانات_الأساسية!A:A, MATCH(19, البيانات_الأساسية!$I:$I, 0)), "") -> 0 | D32: =IFERROR(INDEX(البيانات_الأساسية!B:B, MATCH(19, البيانات_الأساسية!$I:$I, 0)), "") -> 0 | E32: =IFERROR(IF($C$5="الكل", INDEX(البيانات_الأساسية!D:D, MATCH(19, البيانات_الأساسية!$I:$I, 0)), INDEX(البيانات_الأساسية!$V:$AG, MATCH(19, البيانات_الأساسية!$I:$I, 0), VALUE($C$5))), "") -> 0 | F32: =IFERROR(IF($C$5="الكل", INDEX(البيانات_الأساسية!C:C, MATCH(19, البيانات_الأساسية!$I:$I, 0)), INDEX(البيانات_الأساسية!$J:$U, MATCH(19, البيانات_الأساسية!$I:$I, 0), VALUE($C$5))), "") -> 0 | G32: =IFERROR(ROUND(F32/60, 2), "") -> 0 | H32: =IFERROR(ROUND(F32/E32, 2), "") -> 0 | I32: =IFERROR(IF($C$5="الكل", INDEX(البيانات_الأساسية!G:G, MATCH(19, البيانات_الأساسية!$I:$I, 0)), $C$5), "") -> 0
B33: =IF(C33="","", 20) -> 0 | C33: =IFERROR(INDEX(البيانات_الأساسية!A:A, MATCH(20, البيانات_الأساسية!$I:$I, 0)), "") -> 0 | D33: =IFERROR(INDEX(البيانات_الأساسية!B:B, MATCH(20, البيانات_الأساسية!$I:$I, 0)), "") -> 0 | E33: =IFERROR(IF($C$5="الكل", INDEX(البيانات_الأساسية!D:D, MATCH(20, البيانات_الأساسية!$I:$I, 0)), INDEX(البيانات_الأساسية!$V:$AG, MATCH(20, البيانات_الأساسية!$I:$I, 0), VALUE($C$5))), "") -> 0 | F33: =IFERROR(IF($C$5="الكل", INDEX(البيانات_الأساسية!C:C, MATCH(20, البيانات_الأساسية!$I:$I, 0)), INDEX(البيانات_الأساسية!$J:$U, MATCH(20, البيانات_الأساسية!$I:$I, 0), VALUE($C$5))), "") -> 0 | G33: =IFERROR(ROUND(F33/60, 2), "") -> 0 | H33: =IFERROR(ROUND(F33/E33, 2), "") -> 0 | I33: =IFERROR(IF($C$5="الكل", INDEX(البيانات_الأساسية!G:G, MATCH(20, البيانات_الأساسية!$I:$I, 0)), $C$5), "") -> 0
B34: =IF(C34="","", 21) -> 0 | C34: =IFERROR(INDEX(البيانات_الأساسية!A:A, MATCH(21, البيانات_الأساسية!$I:$I, 0)), "") -> 0 | D34: =IFERROR(INDEX(البيانات_الأساسية!B:B, MATCH(21, البيانات_الأساسية!$I:$I, 0)), "") -> 0 | E34: =IFERROR(IF($C$5="الكل", INDEX(البيانات_الأساسية!D:D, MATCH(21, البيانات_الأساسية!$I:$I, 0)), INDEX(البيانات_الأساسية!$V:$AG, MATCH(21, البيانات_الأساسية!$I:$I, 0), VALUE($C$5))), "") -> 0 | F34: =IFERROR(IF($C$5="الكل", INDEX(البيانات_الأساسية!C:C, MATCH(21, البيانات_الأساسية!$I:$I, 0)), INDEX(البيانات_الأساسية!$J:$U, MATCH(21, البيانات_الأساسية!$I:$I, 0), VALUE($C$5))), "") -> 0 | G34: =IFERROR(ROUND(F34/60, 2), "") -> 0 | H34: =IFERROR(ROUND(F34/E34, 2), "") -> 0 | I34: =IFERROR(IF($C$5="الكل", INDEX(البيانات_الأساسية!G:G, MATCH(21, البيانات_الأساسية!$I:$I, 0)), $C$5), "") -> 0
B35: =IF(C35="","", 22) -> 0 | C35: =IFERROR(INDEX(البيانات_الأساسية!A:A, MATCH(22, البيانات_الأساسية!$I:$I, 0)), "") -> 0 | D35: =IFERROR(INDEX(البيانات_الأساسية!B:B, MATCH(22, البيانات_الأساسية!$I:$I, 0)), "") -> 0 | E35: =IFERROR(IF($C$5="الكل", INDEX(البيانات_الأساسية!D:D, MATCH(22, البيانات_الأساسية!$I:$I, 0)), INDEX(البيانات_الأساسية!$V:$AG, MATCH(22, البيانات_الأساسية!$I:$I, 0), VALUE($C$5))), "") -> 0 | F35: =IFERROR(IF($C$5="الكل", INDEX(البيانات_الأساسية!C:C, MATCH(22, البيانات_الأساسية!$I:$I, 0)), INDEX(البيانات_الأساسية!$J:$U, MATCH(22, البيانات_الأساسية!$I:$I, 0), VALUE($C$5))), "") -> 0 | G35: =IFERROR(ROUND(F35/60, 2), "") -> 0 | H35: =IFERROR(ROUND(F35/E35, 2), "") -> 0 | I35: =IFERROR(IF($C$5="الكل", INDEX(البيانات_الأساسية!G:G, MATCH(22, البيانات_الأساسية!$I:$I, 0)), $C$5), "") -> 0
B36: =IF(C36="","", 23) -> 0 | C36: =IFERROR(INDEX(البيانات_الأساسية!A:A, MATCH(23, البيانات_الأساسية!$I:$I, 0)), "") -> 0 | D36: =IFERROR(INDEX(البيانات_الأساسية!B:B, MATCH(23, البيانات_الأساسية!$I:$I, 0)), "") -> 0 | E36: =IFERROR(IF($C$5="الكل", INDEX(البيانات_الأساسية!D:D, MATCH(23, البيانات_الأساسية!$I:$I, 0)), INDEX(البيانات_الأساسية!$V:$AG, MATCH(23, البيانات_الأساسية!$I:$I, 0), VALUE($C$5))), "") -> 0 | F36: =IFERROR(IF($C$5="الكل", INDEX(البيانات_الأساسية!C:C, MATCH(23, البيانات_الأساسية!$I:$I, 0)), INDEX(البيانات_الأساسية!$J:$U, MATCH(23, البيانات_الأساسية!$I:$I, 0), VALUE($C$5))), "") -> 0 | G36: =IFERROR(ROUND(F36/60, 2), "") -> 0 | H36: =IFERROR(ROUND(F36/E36, 2), "") -> 0 | I36: =IFERROR(IF($C$5="الكل", INDEX(البيانات_الأساسية!G:G, MATCH(23, البيانات_الأساسية!$I:$I, 0)), $C$5), "") -> 0
B37: =IF(C37="","", 24) -> 0 | C37: =IFERROR(INDEX(البيانات_الأساسية!A:A, MATCH(24, البيانات_الأساسية!$I:$I, 0)), "") -> 0 | D37: =IFERROR(INDEX(البيانات_الأساسية!B:B, MATCH(24, البيانات_الأساسية!$I:$I, 0)), "") -> 0 | E37: =IFERROR(IF($C$5="الكل", INDEX(البيانات_الأساسية!D:D, MATCH(24, البيانات_الأساسية!$I:$I, 0)), INDEX(البيانات_الأساسية!$V:$AG, MATCH(24, البيانات_الأساسية!$I:$I, 0), VALUE($C$5))), "") -> 0 | F37: =IFERROR(IF($C$5="الكل", INDEX(البيانات_الأساسية!C:C, MATCH(24, البيانات_الأساسية!$I:$I, 0)), INDEX(البيانات_الأساسية!$J:$U, MATCH(24, البيانات_الأساسية!$I:$I, 0), VALUE($C$5))), "") -> 0 | G37: =IFERROR(ROUND(F37/60, 2), "") -> 0 | H37: =IFERROR(ROUND(F37/E37, 2), "") -> 0 | I37: =IFERROR(IF($C$5="الكل", INDEX(البيانات_الأساسية!G:G, MATCH(24, البيانات_الأساسية!$I:$I, 0)), $C$5), "") -> 0
B38: =IF(C38="","", 25) -> 0 | C38: =IFERROR(INDEX(البيانات_الأساسية!A:A, MATCH(25, البيانات_الأساسية!$I:$I, 0)), "") -> 0 | D38: =IFERROR(INDEX(البيانات_الأساسية!B:B, MATCH(25, البيانات_الأساسية!$I:$I, 0)), "") -> 0 | E38: =IFERROR(IF($C$5="الكل", INDEX(البيانات_الأساسية!D:D, MATCH(25, البيانات_الأساسية!$I:$I, 0)), INDEX(البيانات_الأساسية!$V:$AG, MATCH(25, البيانات_الأساسية!$I:$I, 0), VALUE($C$5))), "") -> 0 | F38: =IFERROR(IF($C$5="الكل", INDEX(البيانات_الأساسية!C:C, MATCH(25, البيانات_الأساسية!$I:$I, 0)), INDEX(البيانات_الأساسية!$J:$U, MATCH(25, البيانات_الأساسية!$I:$I, 0), VALUE($C$5))), "") -> 0 | G38: =IFERROR(ROUND(F38/60, 2), "") -> 0 | H38: =IFERROR(ROUND(F38/E38, 2), "") -> 0 | I38: =IFERROR(IF($C$5="الكل", INDEX(البيانات_الأساسية!G:G, MATCH(25, البيانات_الأساسية!$I:$I, 0)), $C$5), "") -> 0
B39: =IF(C39="","", 26) -> 0 | C39: =IFERROR(INDEX(البيانات_الأساسية!A:A, MATCH(26, البيانات_الأساسية!$I:$I, 0)), "") -> 0 | D39: =IFERROR(INDEX(البيانات_الأساسية!B:B, MATCH(26, البيانات_الأساسية!$I:$I, 0)), "") -> 0 | E39: =IFERROR(IF($C$5="الكل", INDEX(البيانات_الأساسية!D:D, MATCH(26, البيانات_الأساسية!$I:$I, 0)), INDEX(البيانات_الأساسية!$V:$AG, MATCH(26, البيانات_الأساسية!$I:$I, 0), VALUE($C$5))), "") -> 0 | F39: =IFERROR(IF($C$5="الكل", INDEX(البيانات_الأساسية!C:C, MATCH(26, البيانات_الأساسية!$I:$I, 0)), INDEX(البيانات_الأساسية!$J:$U, MATCH(26, البيانات_الأساسية!$I:$I, 0), VALUE($C$5))), "") -> 0 | G39: =IFERROR(ROUND(F39/60, 2), "") -> 0 | H39: =IFERROR(ROUND(F39/E39, 2), "") -> 0 | I39: =IFERROR(IF($C$5="الكل", INDEX(البيانات_الأساسية!G:G, MATCH(26, البيانات_الأساسية!$I:$I, 0)), $C$5), "") -> 0
B40: =IF(C40="","", 27) -> 0 | C40: =IFERROR(INDEX(البيانات_الأساسية!A:A, MATCH(27, البيانات_الأساسية!$I:$I, 0)), "") -> 0 | D40: =IFERROR(INDEX(البيانات_الأساسية!B:B, MATCH(27, البيانات_الأساسية!$I:$I, 0)), "") -> 0 | E40: =IFERROR(IF($C$5="الكل", INDEX(البيانات_الأساسية!D:D, MATCH(27, البيانات_الأساسية!$I:$I, 0)), INDEX(البيانات_الأساسية!$V:$AG, MATCH(27, البيانات_الأساسية!$I:$I, 0), VALUE($C$5))), "") -> 0 | F40: =IFERROR(IF($C$5="الكل", INDEX(البيانات_الأساسية!C:C, MATCH(27, البيانات_الأساسية!$I:$I, 0)), INDEX(البيانات_الأساسية!$J:$U, MATCH(27, البيانات_الأساسية!$I:$I, 0), VALUE($C$5))), "") -> 0 | G40: =IFERROR(ROUND(F40/60, 2), "") -> 0 | H40: =IFERROR(ROUND(F40/E40, 2), "") -> 0 | I40: =IFERROR(IF($C$5="الكل", INDEX(البيانات_الأساسية!G:G, MATCH(27, البيانات_الأساسية!$I:$I, 0)), $C$5), "") -> 0
B41: =IF(C41="","", 28) -> 0 | C41: =IFERROR(INDEX(البيانات_الأساسية!A:A, MATCH(28, البيانات_الأساسية!$I:$I, 0)), "") -> 0 | D41: =IFERROR(INDEX(البيانات_الأساسية!B:B, MATCH(28, البيانات_الأساسية!$I:$I, 0)), "") -> 0 | E41: =IFERROR(IF($C$5="الكل", INDEX(البيانات_الأساسية!D:D, MATCH(28, البيانات_الأساسية!$I:$I, 0)), INDEX(البيانات_الأساسية!$V:$AG, MATCH(28, البيانات_الأساسية!$I:$I, 0), VALUE($C$5))), "") -> 0 | F41: =IFERROR(IF($C$5="الكل", INDEX(البيانات_الأساسية!C:C, MATCH(28, البيانات_الأساسية!$I:$I, 0)), INDEX(البيانات_الأساسية!$J:$U, MATCH(28, البيانات_الأساسية!$I:$I, 0), VALUE($C$5))), "") -> 0 | G41: =IFERROR(ROUND(F41/60, 2), "") -> 0 | H41: =IFERROR(ROUND(F41/E41, 2), "") -> 0 | I41: =IFERROR(IF($C$5="الكل", INDEX(البيانات_الأساسية!G:G, MATCH(28, البيانات_الأساسية!$I:$I, 0)), $C$5), "") -> 0
B42: =IF(C42="","", 29) -> 0 | C42: =IFERROR(INDEX(البيانات_الأساسية!A:A, MATCH(29, البيانات_الأساسية!$I:$I, 0)), "") -> 0 | D42: =IFERROR(INDEX(البيانات_الأساسية!B:B, MATCH(29, البيانات_الأساسية!$I:$I, 0)), "") -> 0 | E42: =IFERROR(IF($C$5="الكل", INDEX(البيانات_الأساسية!D:D, MATCH(29, البيانات_الأساسية!$I:$I, 0)), INDEX(البيانات_الأساسية!$V:$AG, MATCH(29, البيانات_الأساسية!$I:$I, 0), VALUE($C$5))), "") -> 0 | F42: =IFERROR(IF($C$5="الكل", INDEX(البيانات_الأساسية!C:C, MATCH(29, البيانات_الأساسية!$I:$I, 0)), INDEX(البيانات_الأساسية!$J:$U, MATCH(29, البيانات_الأساسية!$I:$I, 0), VALUE($C$5))), "") -> 0 | G42: =IFERROR(ROUND(F42/60, 2), "") -> 0 | H42: =IFERROR(ROUND(F42/E42, 2), "") -> 0 | I42: =IFERROR(IF($C$5="الكل", INDEX(البيانات_الأساسية!G:G, MATCH(29, البيانات_الأساسية!$I:$I, 0)), $C$5), "") -> 0
B43: =IF(C43="","", 30) -> 0 | C43: =IFERROR(INDEX(البيانات_الأساسية!A:A, MATCH(30, البيانات_الأساسية!$I:$I, 0)), "") -> 0 | D43: =IFERROR(INDEX(البيانات_الأساسية!B:B, MATCH(30, البيانات_الأساسية!$I:$I, 0)), "") -> 0 | E43: =IFERROR(IF($C$5="الكل", INDEX(البيانات_الأساسية!D:D, MATCH(30, البيانات_الأساسية!$I:$I, 0)), INDEX(البيانات_الأساسية!$V:$AG, MATCH(30, البيانات_الأساسية!$I:$I, 0), VALUE($C$5))), "") -> 0 | F43: =IFERROR(IF($C$5="الكل", INDEX(البيانات_الأساسية!C:C, MATCH(30, البيانات_الأساسية!$I:$I, 0)), INDEX(البيانات_الأساسية!$J:$U, MATCH(30, البيانات_الأساسية!$I:$I, 0), VALUE($C$5))), "") -> 0 | G43: =IFERROR(ROUND(F43/60, 2), "") -> 0 | H43: =IFERROR(ROUND(F43/E43, 2), "") -> 0 | I43: =IFERROR(IF($C$5="الكل", INDEX(البيانات_الأساسية!G:G, MATCH(30, البيانات_الأساسية!$I:$I, 0)), $C$5), "") -> 0
B44: =IF(C44="","", 31) -> 0 | C44: =IFERROR(INDEX(البيانات_الأساسية!A:A, MATCH(31, البيانات_الأساسية!$I:$I, 0)), "") -> 0 | D44: =IFERROR(INDEX(البيانات_الأساسية!B:B, MATCH(31, البيانات_الأساسية!$I:$I, 0)), "") -> 0 | E44: =IFERROR(IF($C$5="الكل", INDEX(البيانات_الأساسية!D:D, MATCH(31, البيانات_الأساسية!$I:$I, 0)), INDEX(البيانات_الأساسية!$V:$AG, MATCH(31, البيانات_الأساسية!$I:$I, 0), VALUE($C$5))), "") -> 0 | F44: =IFERROR(IF($C$5="الكل", INDEX(البيانات_الأساسية!C:C, MATCH(31, البيانات_الأساسية!$I:$I, 0)), INDEX(البيانات_الأساسية!$J:$U, MATCH(31, البيانات_الأساسية!$I:$I, 0), VALUE($C$5))), "") -> 0 | G44: =IFERROR(ROUND(F44/60, 2), "") -> 0 | H44: =IFERROR(ROUND(F44/E44, 2), "") -> 0 | I44: =IFERROR(IF($C$5="الكل", INDEX(البيانات_الأساسية!G:G, MATCH(31, البيانات_الأساسية!$I:$I, 0)), $C$5), "") -> 0
B45: =IF(C45="","", 32) -> 0 | C45: =IFERROR(INDEX(البيانات_الأساسية!A:A, MATCH(32, البيانات_الأساسية!$I:$I, 0)), "") -> 0 | D45: =IFERROR(INDEX(البيانات_الأساسية!B:B, MATCH(32, البيانات_الأساسية!$I:$I, 0)), "") -> 0 | E45: =IFERROR(IF($C$5="الكل", INDEX(البيانات_الأساسية!D:D, MATCH(32, البيانات_الأساسية!$I:$I, 0)), INDEX(البيانات_الأساسية!$V:$AG, MATCH(32, البيانات_الأساسية!$I:$I, 0), VALUE($C$5))), "") -> 0 | F45: =IFERROR(IF($C$5="الكل", INDEX(البيانات_الأساسية!C:C, MATCH(32, البيانات_الأساسية!$I:$I, 0)), INDEX(البيانات_الأساسية!$J:$U, MATCH(32, البيانات_الأساسية!$I:$I, 0), VALUE($C$5))), "") -> 0 | G45: =IFERROR(ROUND(F45/60, 2), "") -> 0 | H45: =IFERROR(ROUND(F45/E45, 2), "") -> 0 | I45: =IFERROR(IF($C$5="الكل", INDEX(البيانات_الأساسية!G:G, MATCH(32, البيانات_الأساسية!$I:$I, 0)), $C$5), "") -> 0
B46: =IF(C46="","", 33) -> 0 | C46: =IFERROR(INDEX(البيانات_الأساسية!A:A, MATCH(33, البيانات_الأساسية!$I:$I, 0)), "") -> 0 | D46: =IFERROR(INDEX(البيانات_الأساسية!B:B, MATCH(33, البيانات_الأساسية!$I:$I, 0)), "") -> 0 | E46: =IFERROR(IF($C$5="الكل", INDEX(البيانات_الأساسية!D:D, MATCH(33, البيانات_الأساسية!$I:$I, 0)), INDEX(البيانات_الأساسية!$V:$AG, MATCH(33, البيانات_الأساسية!$I:$I, 0), VALUE($C$5))), "") -> 0 | F46: =IFERROR(IF($C$5="الكل", INDEX(البيانات_الأساسية!C:C, MATCH(33, البيانات_الأساسية!$I:$I, 0)), INDEX(البيانات_الأساسية!$J:$U, MATCH(33, البيانات_الأساسية!$I:$I, 0), VALUE($C$5))), "") -> 0 | G46: =IFERROR(ROUND(F46/60, 2), "") -> 0 | H46: =IFERROR(ROUND(F46/E46, 2), "") -> 0 | I46: =IFERROR(IF($C$5="الكل", INDEX(البيانات_الأساسية!G:G, MATCH(33, البيانات_الأساسية!$I:$I, 0)), $C$5), "") -> 0
...
