Workbook

Sheet قوائم_النظام
A1: الكل
A2: الإدارة العامة - القدس
A3: البرنامج الدولي
A4: العلاقات العامة
A5: دائرة التخطيط والجودة
A6: شؤون الطلبة
A7: عمادة الدراسات العليا والبحث العلمي_compressed (1)
A8: عمادة القبول والتسجيل والامتحانات_compressed (1)
A9: فرع الخليل
A10: فرع القدس
A11: فرع بيت لحم
A12: فرع جنين
... A23: مركز تكنولوجيا المعلومات

Sheet البيانات_الأساسية
A1: الفرع | B1: اسم الموظف | C1: إجمالي الدقائق | D1: إجمالي الساعات | E1: عدد التأخيرات | F1: متوسط التأخير | G1: الأشهر المسجلة | H1: Match_Flag | I1: Running_Count
A2: فرع رام الله والبيرة | B2: عز الدين محمد مصطفى أبو نزهة | C2: 7969 | D2: 132.82 | E2: 90 | F2: 88.54 | G2: 01، 02، 03، 04، 05، 06، 07 | H2: =IF(OR(لوحة_القيادة!$C$4="الكل", A2=لوحة_القيادة!$C$4), 1, 0) -> 0 | I2: =IF(H2=1, SUM($H$2:H2), "") -> 0
A3: فرع رام الله والبيرة | B3: محمد رزق رشيد دارأحمد | C3: 6358 | D3: 105.97 | E3: 76 | F3: 83.66 | G3: 01، 02، 03، 04، 05، 06، 07 | H3: =IF(OR(لوحة_القيادة!$C$4="الكل", A3=لوحة_القيادة!$C$4), 1, 0) -> 0 | I3: =IF(H3=1, SUM($H$2:H3), "") -> 0
A4: الإدارة العامة - القدس | B4: رامي نجيب محمود خليل | C4: 5561 | D4: 92.68 | E4: 73 | F4: 76.18 | G4: 01، 02، 03، 04، 05، 06، 07 | H4: =IF(OR(لوحة_القيادة!$C$4="الكل", A4=لوحة_القيادة!$C$4), 1, 0) -> 0 | I4: =IF(H4=1, SUM($H$2:H4), "") -> 0
A5: مركز التعليم الرقمي | B5: ابراهيم محمد ابراهيم ابو تركي | C5: 4976 | D5: 82.93 | E5: 105 | F5: 47.39 | G5: 01، 02، 03، 04، 05، 06، 07 | H5: =IF(OR(لوحة_القيادة!$C$4="الكل", A5=لوحة_القيادة!$C$4), 1, 0) -> 0 | I5: =IF(H5=1, SUM($H$2:H5), "") -> 0
A6: عمادة القبول والتسجيل والامتحانات_compressed (1) | B6: احمد ابراهيم محمد دلال | C6: 4940 | D6: 82.33 | E6: 96 | F6: 51.46 | G6: 01، 02، 03، 04، 05، 06، 07 | H6: =IF(OR(لوحة_القيادة!$C$4="الكل", A6=لوحة_القيادة!$C$4), 1, 0) -> 0 | I6: =IF(H6=1, SUM($H$2:H6), "") -> 0
A7: مركز التعليم الرقمي | B7: فؤاد محمد مصطفى صالح | C7: 4026 | D7: 67.1 | E7: 101 | F7: 39.86 | G7: 01، 02، 03، 04، 05، 06، 07 | H7: =IF(OR(لوحة_القيادة!$C$4="الكل", A7=لوحة_القيادة!$C$4), 1, 0) -> 0 | I7: =IF(H7=1, SUM($H$2:H7), "") -> 0
A8: الإدارة العامة - القدس | B8: باسمة احمد محمد ابوعواد | C8: 3922 | D8: 65.37 | E8: 90 | F8: 43.58 | G8: 01، 02، 03، 04، 05، 06، 07 | H8: =IF(OR(لوحة_القيادة!$C$4="الكل", A8=لوحة_القيادة!$C$4), 1, 0) -> 0 | I8: =IF(H8=1, SUM($H$2:H8), "") -> 0
A9: فرع جنين | B9: حسن فايز حسن قصراوي | C9: 3511 | D9: 58.52 | E9: 64 | F9: 54.86 | G9: 01، 02، 03، 04، 05، 06، 07 | H9: =IF(OR(لوحة_القيادة!$C$4="الكل", A9=لوحة_القيادة!$C$4), 1, 0) -> 0 | I9: =IF(H9=1, SUM($H$2:H9), "") -> 0
A10: عمادة القبول والتسجيل والامتحانات_compressed (1) | B10: احمد حسني حسن سلمان | C10: 3475 | D10: 57.92 | E10: 90 | F10: 38.61 | G10: 01، 02، 03، 04، 05، 06، 07 | H10: =IF(OR(لوحة_القيادة!$C$4="الكل", A10=لوحة_القيادة!$C$4), 1, 0) -> 0 | I10: =IF(H10=1, SUM($H$2:H10), "") -> 0
A11: عمادة القبول والتسجيل والامتحانات_compressed (1) | B11: ميسون محمد موسى حموده | C11: 3394 | D11: 56.57 | E11: 98 | F11: 34.63 | G11: 01، 02، 03، 04، 05، 06، 07 | H11: =IF(OR(لوحة_القيادة!$C$4="الكل", A11=لوحة_القيادة!$C$4), 1, 0) -> 0 | I11: =IF(H11=1, SUM($H$2:H11), "") -> 0
A12: فرع طولكرم | B12: جهاد تحسين أحمد طقاطقة | C12: 3356 | D12: 55.93 | E12: 69 | F12: 48.64 | G12: 01، 02، 03، 04، 05، 06، 07 | H12: =IF(OR(لوحة_القيادة!$C$4="الكل", A12=لوحة_القيادة!$C$4), 1, 0) -> 0 | I12: =IF(H12=1, SUM($H$2:H12), "") -> 0
A13: عمادة الدراسات العليا والبحث العلمي_compressed (1) | B13: كميل غالب محمد زيد | C13: 3355 | D13: 55.92 | E13: 91 | F13: 36.87 | G13: 01، 02، 03، 04، 05، 06، 07 | H13: =IF(OR(لوحة_القيادة!$C$4="الكل", A13=لوحة_القيادة!$C$4), 1, 0) -> 0 | I13: =IF(H13=1, SUM($H$2:H13), "") -> 0
... A455: فرع طولكرم | B455: سعادة خالد محمد ابو شملة | C455: 1 | D455: 0.02 | E455: 1 | F455: 1 | G455: 01، 03، 04، 07 | H455: =IF(OR(لوحة_القيادة!$C$4="الكل", A455=لوحة_القيادة!$C$4), 1, 0) -> 0 | I455: =IF(H455=1, SUM($H$2:H455), "") -> 0

Sheet لوحة_القيادة
B2: المنصة الإدارية الذكية لتحليل الالتزام (بدون Pivot)
B4: اختر الفرع للتحليل: | C4: الكل
B6: إجمالي الموظفين | D6: إجمالي التأخيرات | F6: إجمالي الدقائق | H6: إجمالي الساعات
B7: =IF($C$4="الكل", COUNTA(البيانات_الأساسية!B:B)-1, COUNTIF(البيانات_الأساسية!A:A, $C$4)) -> 0 | D7: =IF($C$4="الكل", SUM(البيانات_الأساسية!E:E), SUMIF(البيانات_الأساسية!A:A, $C$4, البيانات_الأساسية!E:E)) -> 0 | F7: =IF($C$4="الكل", SUM(البيانات_الأساسية!C:C), SUMIF(البيانات_الأساسية!A:A, $C$4, البيانات_الأساسية!C:C)) -> 0 | H7: =IF($C$4="الكل", SUM(البيانات_الأساسية!D:D), SUMIF(البيانات_الأساسية!A:A, $C$4, البيانات_الأساسية!D:D)) -> 0
B10: الجدول التفاعلي للموظفين (يتغير فوراً باختيار الفرع من الأعلى)
B12: الفرع | C12: اسم الموظف | D12: إجمالي الدقائق | E12: إجمالي الساعات | F12: عدد التأخيرات | G12: متوسط التأخير | H12: الأشهر المسجلة
B13: =IFERROR(INDEX(البيانات_الأساسية!A:A, MATCH(1, البيانات_الأساسية!$I:$I, 0)), "") -> 0 | C13: =IFERROR(INDEX(البيانات_الأساسية!B:B, MATCH(1, البيانات_الأساسية!$I:$I, 0)), "") -> 0 | D13: =IFERROR(INDEX(البيانات_الأساسية!C:C, MATCH(1, البيانات_الأساسية!$I:$I, 0)), "") -> 0 | E13: =IFERROR(INDEX(البيانات_الأساسية!D:D, MATCH(1, البيانات_الأساسية!$I:$I, 0)), "") -> 0 | F13: =IFERROR(INDEX(البيانات_الأساسية!E:E, MATCH(1, البيانات_الأساسية!$I:$I, 0)), "") -> 0 | G13: =IFERROR(INDEX(البيانات_الأساسية!F:F, MATCH(1, البيانات_الأساسية!$I:$I, 0)), "") -> 0 | H13: =IFERROR(INDEX(البيانات_الأساسية!G:G, MATCH(1, البيانات_الأساسية!$I:$I, 0)), "") -> 0
B14: =IFERROR(INDEX(البيانات_الأساسية!A:A, MATCH(2, البيانات_الأساسية!$I:$I, 0)), "") -> 0 | C14: =IFERROR(INDEX(البيانات_الأساسية!B:B, MATCH(2, البيانات_الأساسية!$I:$I, 0)), "") -> 0 | D14: =IFERROR(INDEX(البيانات_الأساسية!C:C, MATCH(2, البيانات_الأساسية!$I:$I, 0)), "") -> 0 | E14: =IFERROR(INDEX(البيانات_الأساسية!D:D, MATCH(2, البيانات_الأساسية!$I:$I, 0)), "") -> 0 | F14: =IFERROR(INDEX(البيانات_الأساسية!E:E, MATCH(2, البيانات_الأساسية!$I:$I, 0)), "") -> 0 | G14: =IFERROR(INDEX(البيانات_الأساسية!F:F, MATCH(2, البيانات_الأساسية!$I:$I, 0)), "") -> 0 | H14: =IFERROR(INDEX(البيانات_الأساسية!G:G, MATCH(2, البيانات_الأساسية!$I:$I, 0)), "") -> 0
B15: =IFERROR(INDEX(البيانات_الأساسية!A:A, MATCH(3, البيانات_الأساسية!$I:$I, 0)), "") -> 0 | C15: =IFERROR(INDEX(البيانات_الأساسية!B:B, MATCH(3, البيانات_الأساسية!$I:$I, 0)), "") -> 0 | D15: =IFERROR(INDEX(البيانات_الأساسية!C:C, MATCH(3, البيانات_الأساسية!$I:$I, 0)), "") -> 0 | E15: =IFERROR(INDEX(البيانات_الأساسية!D:D, MATCH(3, البيانات_الأساسية!$I:$I, 0)), "") -> 0 | F15: =IFERROR(INDEX(البيانات_الأساسية!E:E, MATCH(3, البيانات_الأساسية!$I:$I, 0)), "") -> 0 | G15: =IFERROR(INDEX(البيانات_الأساسية!F:F, MATCH(3, البيانات_الأساسية!$I:$I, 0)), "") -> 0 | H15: =IFERROR(INDEX(البيانات_الأساسية!G:G, MATCH(3, البيانات_الأساسية!$I:$I, 0)), "") -> 0
B16: =IFERROR(INDEX(البيانات_الأساسية!A:A, MATCH(4, البيانات_الأساسية!$I:$I, 0)), "") -> 0 | C16: =IFERROR(INDEX(البيانات_الأساسية!B:B, MATCH(4, البيانات_الأساسية!$I:$I, 0)), "") -> 0 | D16: =IFERROR(INDEX(البيانات_الأساسية!C:C, MATCH(4, البيانات_الأساسية!$I:$I, 0)), "") -> 0 | E16: =IFERROR(INDEX(البيانات_الأساسية!D:D, MATCH(4, البيانات_الأساسية!$I:$I, 0)), "") -> 0 | F16: =IFERROR(INDEX(البيانات_الأساسية!E:E, MATCH(4, البيانات_الأساسية!$I:$I, 0)), "") -> 0 | G16: =IFERROR(INDEX(البيانات_الأساسية!F:F, MATCH(4, البيانات_الأساسية!$I:$I, 0)), "") -> 0 | H16: =IFERROR(INDEX(البيانات_الأساسية!G:G, MATCH(4, البيانات_الأساسية!$I:$I, 0)), "") -> 0
B17: =IFERROR(INDEX(البيانات_الأساسية!A:A, MATCH(5, البيانات_الأساسية!$I:$I, 0)), "") -> 0 | C17: =IFERROR(INDEX(البيانات_الأساسية!B:B, MATCH(5, البيانات_الأساسية!$I:$I, 0)), "") -> 0 | D17: =IFERROR(INDEX(البيانات_الأساسية!C:C, MATCH(5, البيانات_الأساسية!$I:$I, 0)), "") -> 0 | E17: =IFERROR(INDEX(البيانات_الأساسية!D:D, MATCH(5, البيانات_الأساسية!$I:$I, 0)), "") -> 0 | F17: =IFERROR(INDEX(البيانات_الأساسية!E:E, MATCH(5, البيانات_الأساسية!$I:$I, 0)), "") -> 0 | G17: =IFERROR(INDEX(البيانات_الأساسية!F:F, MATCH(5, البيانات_الأساسية!$I:$I, 0)), "") -> 0 | H17: =IFERROR(INDEX(البيانات_الأساسية!G:G, MATCH(5, البيانات_الأساسية!$I:$I, 0)), "") -> 0
B18: =IFERROR(INDEX(البيانات_الأساسية!A:A, MATCH(6, البيانات_الأساسية!$I:$I, 0)), "") -> 0 | C18: =IFERROR(INDEX(البيانات_الأساسية!B:B, MATCH(6, البيانات_الأساسية!$I:$I, 0)), "") -> 0 | D18: =IFERROR(INDEX(البيانات_الأساسية!C:C, MATCH(6, البيانات_الأساسية!$I:$I, 0)), "") -> 0 | E18: =IFERROR(INDEX(البيانات_الأساسية!D:D, MATCH(6, البيانات_الأساسية!$I:$I, 0)), "") -> 0 | F18: =IFERROR(INDEX(البيانات_الأساسية!E:E, MATCH(6, البيانات_الأساسية!$I:$I, 0)), "") -> 0 | G18: =IFERROR(INDEX(البيانات_الأساسية!F:F, MATCH(6, البيانات_الأساسية!$I:$I, 0)), "") -> 0 | H18: =IFERROR(INDEX(البيانات_الأساسية!G:G, MATCH(6, البيانات_الأساسية!$I:$I, 0)), "") -> 0
B19: =IFERROR(INDEX(البيانات_الأساسية!A:A, MATCH(7, البيانات_الأساسية!$I:$I, 0)), "") -> 0 | C19: =IFERROR(INDEX(البيانات_الأساسية!B:B, MATCH(7, البيانات_الأساسية!$I:$I, 0)), "") -> 0 | D19: =IFERROR(INDEX(البيانات_الأساسية!C:C, MATCH(7, البيانات_الأساسية!$I:$I, 0)), "") -> 0 | E19: =IFERROR(INDEX(البيانات_الأساسية!D:D, MATCH(7, البيانات_الأساسية!$I:$I, 0)), "") -> 0 | F19: =IFERROR(INDEX(البيانات_الأساسية!E:E, MATCH(7, البيانات_الأساسية!$I:$I, 0)), "") -> 0 | G19: =IFERROR(INDEX(البيانات_الأساسية!F:F, MATCH(7, البيانات_الأساسية!$I:$I, 0)), "") -> 0 | H19: =IFERROR(INDEX(البيانات_الأساسية!G:G, MATCH(7, البيانات_الأساسية!$I:$I, 0)), "") -> 0
B20: =IFERROR(INDEX(البيانات_الأساسية!A:A, MATCH(8, البيانات_الأساسية!$I:$I, 0)), "") -> 0 | C20: =IFERROR(INDEX(البيانات_الأساسية!B:B, MATCH(8, البيانات_الأساسية!$I:$I, 0)), "") -> 0 | D20: =IFERROR(INDEX(البيانات_الأساسية!C:C, MATCH(8, البيانات_الأساسية!$I:$I, 0)), "") -> 0 | E20: =IFERROR(INDEX(البيانات_الأساسية!D:D, MATCH(8, البيانات_الأساسية!$I:$I, 0)), "") -> 0 | F20: =IFERROR(INDEX(البيانات_الأساسية!E:E, MATCH(8, البيانات_الأساسية!$I:$I, 0)), "") -> 0 | G20: =IFERROR(INDEX(البيانات_الأساسية!F:F, MATCH(8, البيانات_الأساسية!$I:$I, 0)), "") -> 0 | H20: =IFERROR(INDEX(البيانات_الأساسية!G:G, MATCH(8, البيانات_الأساسية!$I:$I, 0)), "") -> 0
B21: =IFERROR(INDEX(البيانات_الأساسية!A:A, MATCH(9, البيانات_الأساسية!$I:$I, 0)), "") -> 0 | C21: =IFERROR(INDEX(البيانات_الأساسية!B:B, MATCH(9, البيانات_الأساسية!$I:$I, 0)), "") -> 0 | D21: =IFERROR(INDEX(البيانات_الأساسية!C:C, MATCH(9, البيانات_الأساسية!$I:$I, 0)), "") -> 0 | E21: =IFERROR(INDEX(البيانات_الأساسية!D:D, MATCH(9, البيانات_الأساسية!$I:$I, 0)), "") -> 0 | F21: =IFERROR(INDEX(البيانات_الأساسية!E:E, MATCH(9, البيانات_الأساسية!$I:$I, 0)), "") -> 0 | G21: =IFERROR(INDEX(البيانات_الأساسية!F:F, MATCH(9, البيانات_الأساسية!$I:$I, 0)), "") -> 0 | H21: =IFERROR(INDEX(البيانات_الأساسية!G:G, MATCH(9, البيانات_الأساسية!$I:$I, 0)), "") -> 0
B22: =IFERROR(INDEX(البيانات_الأساسية!A:A, MATCH(10, البيانات_الأساسية!$I:$I, 0)), "") -> 0 | C22: =IFERROR(INDEX(البيانات_الأساسية!B:B, MATCH(10, البيانات_الأساسية!$I:$I, 0)), "") -> 0 | D22: =IFERROR(INDEX(البيانات_الأساسية!C:C, MATCH(10, البيانات_الأساسية!$I:$I, 0)), "") -> 0 | E22: =IFERROR(INDEX(البيانات_الأساسية!D:D, MATCH(10, البيانات_الأساسية!$I:$I, 0)), "") -> 0 | F22: =IFERROR(INDEX(البيانات_الأساسية!E:E, MATCH(10, البيانات_الأساسية!$I:$I, 0)), "") -> 0 | G22: =IFERROR(INDEX(البيانات_الأساسية!F:F, MATCH(10, البيانات_الأساسية!$I:$I, 0)), "") -> 0 | H22: =IFERROR(INDEX(البيانات_الأساسية!G:G, MATCH(10, البيانات_الأساسية!$I:$I, 0)), "") -> 0
B23: =IFERROR(INDEX(البيانات_الأساسية!A:A, MATCH(11, البيانات_الأساسية!$I:$I, 0)), "") -> 0 | C23: =IFERROR(INDEX(البيانات_الأساسية!B:B, MATCH(11, البيانات_الأساسية!$I:$I, 0)), "") -> 0 | D23: =IFERROR(INDEX(البيانات_الأساسية!C:C, MATCH(11, البيانات_الأساسية!$I:$I, 0)), "") -> 0 | E23: =IFERROR(INDEX(البيانات_الأساسية!D:D, MATCH(11, البيانات_الأساسية!$I:$I, 0)), "") -> 0 | F23: =IFERROR(INDEX(البيانات_الأساسية!E:E, MATCH(11, البيانات_الأساسية!$I:$I, 0)), "") -> 0 | G23: =IFERROR(INDEX(البيانات_الأساسية!F:F, MATCH(11, البيانات_الأساسية!$I:$I, 0)), "") -> 0 | H23: =IFERROR(INDEX(البيانات_الأساسية!G:G, MATCH(11, البيانات_الأساسية!$I:$I, 0)), "") -> 0
B24: =IFERROR(INDEX(البيانات_الأساسية!A:A, MATCH(12, البيانات_الأساسية!$I:$I, 0)), "") -> 0 | C24: =IFERROR(INDEX(البيانات_الأساسية!B:B, MATCH(12, البيانات_الأساسية!$I:$I, 0)), "") -> 0 | D24: =IFERROR(INDEX(البيانات_الأساسية!C:C, MATCH(12, البيانات_الأساسية!$I:$I, 0)), "") -> 0 | E24: =IFERROR(INDEX(البيانات_الأساسية!D:D, MATCH(12, البيانات_الأساسية!$I:$I, 0)), "") -> 0 | F24: =IFERROR(INDEX(البيانات_الأساسية!E:E, MATCH(12, البيانات_الأساسية!$I:$I, 0)), "") -> 0 | G24: =IFERROR(INDEX(البيانات_الأساسية!F:F, MATCH(12, البيانات_الأساسية!$I:$I, 0)), "") -> 0 | H24: =IFERROR(INDEX(البيانات_الأساسية!G:G, MATCH(12, البيانات_الأساسية!$I:$I, 0)), "") -> 0
B25: =IFERROR(INDEX(البيانات_الأساسية!A:A, MATCH(13, البيانات_الأساسية!$I:$I, 0)), "") -> 0 | C25: =IFERROR(INDEX(البيانات_الأساسية!B:B, MATCH(13, البيانات_الأساسية!$I:$I, 0)), "") -> 0 | D25: =IFERROR(INDEX(البيانات_الأساسية!C:C, MATCH(13, البيانات_الأساسية!$I:$I, 0)), "") -> 0 | E25: =IFERROR(INDEX(البيانات_الأساسية!D:D, MATCH(13, البيانات_الأساسية!$I:$I, 0)), "") -> 0 | F25: =IFERROR(INDEX(البيانات_الأساسية!E:E, MATCH(13, البيانات_الأساسية!$I:$I, 0)), "") -> 0 | G25: =IFERROR(INDEX(البيانات_الأساسية!F:F, MATCH(13, البيانات_الأساسية!$I:$I, 0)), "") -> 0 | H25: =IFERROR(INDEX(البيانات_الأساسية!G:G, MATCH(13, البيانات_الأساسية!$I:$I, 0)), "") -> 0
B26: =IFERROR(INDEX(البيانات_الأساسية!A:A, MATCH(14, البيانات_الأساسية!$I:$I, 0)), "") -> 0 | C26: =IFERROR(INDEX(البيانات_الأساسية!B:B, MATCH(14, البيانات_الأساسية!$I:$I, 0)), "") -> 0 | D26: =IFERROR(INDEX(البيانات_الأساسية!C:C, MATCH(14, البيانات_الأساسية!$I:$I, 0)), "") -> 0 | E26: =IFERROR(INDEX(البيانات_الأساسية!D:D, MATCH(14, البيانات_الأساسية!$I:$I, 0)), "") -> 0 | F26: =IFERROR(INDEX(البيانات_الأساسية!E:E, MATCH(14, البيانات_الأساسية!$I:$I, 0)), "") -> 0 | G26: =IFERROR(INDEX(البيانات_الأساسية!F:F, MATCH(14, البيانات_الأساسية!$I:$I, 0)), "") -> 0 | H26: =IFERROR(INDEX(البيانات_الأساسية!G:G, MATCH(14, البيانات_الأساسية!$I:$I, 0)), "") -> 0
B27: =IFERROR(INDEX(البيانات_الأساسية!A:A, MATCH(15, البيانات_الأساسية!$I:$I, 0)), "") -> 0 | C27: =IFERROR(INDEX(البيانات_الأساسية!B:B, MATCH(15, البيانات_الأساسية!$I:$I, 0)), "") -> 0 | D27: =IFERROR(INDEX(البيانات_الأساسية!C:C, MATCH(15, البيانات_الأساسية!$I:$I, 0)), "") -> 0 | E27: =IFERROR(INDEX(البيانات_الأساسية!D:D, MATCH(15, البيانات_الأساسية!$I:$I, 0)), "") -> 0 | F27: =IFERROR(INDEX(البيانات_الأساسية!E:E, MATCH(15, البيانات_الأساسية!$I:$I, 0)), "") -> 0 | G27: =IFERROR(INDEX(البيانات_الأساسية!F:F, MATCH(15, البيانات_الأساسية!$I:$I, 0)), "") -> 0 | H27: =IFERROR(INDEX(البيانات_الأساسية!G:G, MATCH(15, البيانات_الأساسية!$I:$I, 0)), "") -> 0
B28: =IFERROR(INDEX(البيانات_الأساسية!A:A, MATCH(16, البيانات_الأساسية!$I:$I, 0)), "") -> 0 | C28: =IFERROR(INDEX(البيانات_الأساسية!B:B, MATCH(16, البيانات_الأساسية!$I:$I, 0)), "") -> 0 | D28: =IFERROR(INDEX(البيانات_الأساسية!C:C, MATCH(16, البيانات_الأساسية!$I:$I, 0)), "") -> 0 | E28: =IFERROR(INDEX(البيانات_الأساسية!D:D, MATCH(16, البيانات_الأساسية!$I:$I, 0)), "") -> 0 | F28: =IFERROR(INDEX(البيانات_الأساسية!E:E, MATCH(16, البيانات_الأساسية!$I:$I, 0)), "") -> 0 | G28: =IFERROR(INDEX(البيانات_الأساسية!F:F, MATCH(16, البيانات_الأساسية!$I:$I, 0)), "") -> 0 | H28: =IFERROR(INDEX(البيانات_الأساسية!G:G, MATCH(16, البيانات_الأساسية!$I:$I, 0)), "") -> 0
B29: =IFERROR(INDEX(البيانات_الأساسية!A:A, MATCH(17, البيانات_الأساسية!$I:$I, 0)), "") -> 0 | C29: =IFERROR(INDEX(البيانات_الأساسية!B:B, MATCH(17, البيانات_الأساسية!$I:$I, 0)), "") -> 0 | D29: =IFERROR(INDEX(البيانات_الأساسية!C:C, MATCH(17, البيانات_الأساسية!$I:$I, 0)), "") -> 0 | E29: =IFERROR(INDEX(البيانات_الأساسية!D:D, MATCH(17, البيانات_الأساسية!$I:$I, 0)), "") -> 0 | F29: =IFERROR(INDEX(البيانات_الأساسية!E:E, MATCH(17, البيانات_الأساسية!$I:$I, 0)), "") -> 0 | G29: =IFERROR(INDEX(البيانات_الأساسية!F:F, MATCH(17, البيانات_الأساسية!$I:$I, 0)), "") -> 0 | H29: =IFERROR(INDEX(البيانات_الأساسية!G:G, MATCH(17, البيانات_الأساسية!$I:$I, 0)), "") -> 0
B30: =IFERROR(INDEX(البيانات_الأساسية!A:A, MATCH(18, البيانات_الأساسية!$I:$I, 0)), "") -> 0 | C30: =IFERROR(INDEX(البيانات_الأساسية!B:B, MATCH(18, البيانات_الأساسية!$I:$I, 0)), "") -> 0 | D30: =IFERROR(INDEX(البيانات_الأساسية!C:C, MATCH(18, البيانات_الأساسية!$I:$I, 0)), "") -> 0 | E30: =IFERROR(INDEX(البيانات_الأساسية!D:D, MATCH(18, البيانات_الأساسية!$I:$I, 0)), "") -> 0 | F30: =IFERROR(INDEX(البيانات_الأساسية!E:E, MATCH(18, البيانات_الأساسية!$I:$I, 0)), "") -> 0 | G30: =IFERROR(INDEX(البيانات_الأساسية!F:F, MATCH(18, البيانات_الأساسية!$I:$I, 0)), "") -> 0 | H30: =IFERROR(INDEX(البيانات_الأساسية!G:G, MATCH(18, البيانات_الأساسية!$I:$I, 0)), "") -> 0
B31: =IFERROR(INDEX(البيانات_الأساسية!A:A, MATCH(19, البيانات_الأساسية!$I:$I, 0)), "") -> 0 | C31: =IFERROR(INDEX(البيانات_الأساسية!B:B, MATCH(19, البيانات_الأساسية!$I:$I, 0)), "") -> 0 | D31: =IFERROR(INDEX(البيانات_الأساسية!C:C, MATCH(19, البيانات_الأساسية!$I:$I, 0)), "") -> 0 | E31: =IFERROR(INDEX(البيانات_الأساسية!D:D, MATCH(19, البيانات_الأساسية!$I:$I, 0)), "") -> 0 | F31: =IFERROR(INDEX(البيانات_الأساسية!E:E, MATCH(19, البيانات_الأساسية!$I:$I, 0)), "") -> 0 | G31: =IFERROR(INDEX(البيانات_الأساسية!F:F, MATCH(19, البيانات_الأساسية!$I:$I, 0)), "") -> 0 | H31: =IFERROR(INDEX(البيانات_الأساسية!G:G, MATCH(19, البيانات_الأساسية!$I:$I, 0)), "") -> 0
B32: =IFERROR(INDEX(البيانات_الأساسية!A:A, MATCH(20, البيانات_الأساسية!$I:$I, 0)), "") -> 0 | C32: =IFERROR(INDEX(البيانات_الأساسية!B:B, MATCH(20, البيانات_الأساسية!$I:$I, 0)), "") -> 0 | D32: =IFERROR(INDEX(البيانات_الأساسية!C:C, MATCH(20, البيانات_الأساسية!$I:$I, 0)), "") -> 0 | E32: =IFERROR(INDEX(البيانات_الأساسية!D:D, MATCH(20, البيانات_الأساسية!$I:$I, 0)), "") -> 0 | F32: =IFERROR(INDEX(البيانات_الأساسية!E:E, MATCH(20, البيانات_الأساسية!$I:$I, 0)), "") -> 0 | G32: =IFERROR(INDEX(البيانات_الأساسية!F:F, MATCH(20, البيانات_الأساسية!$I:$I, 0)), "") -> 0 | H32: =IFERROR(INDEX(البيانات_الأساسية!G:G, MATCH(20, البيانات_الأساسية!$I:$I, 0)), "") -> 0
B33: =IFERROR(INDEX(البيانات_الأساسية!A:A, MATCH(21, البيانات_الأساسية!$I:$I, 0)), "") -> 0 | C33: =IFERROR(INDEX(البيانات_الأساسية!B:B, MATCH(21, البيانات_الأساسية!$I:$I, 0)), "") -> 0 | D33: =IFERROR(INDEX(البيانات_الأساسية!C:C, MATCH(21, البيانات_الأساسية!$I:$I, 0)), "") -> 0 | E33: =IFERROR(INDEX(البيانات_الأساسية!D:D, MATCH(21, البيانات_الأساسية!$I:$I, 0)), "") -> 0 | F33: =IFERROR(INDEX(البيانات_الأساسية!E:E, MATCH(21, البيانات_الأساسية!$I:$I, 0)), "") -> 0 | G33: =IFERROR(INDEX(البيانات_الأساسية!F:F, MATCH(21, البيانات_الأساسية!$I:$I, 0)), "") -> 0 | H33: =IFERROR(INDEX(البيانات_الأساسية!G:G, MATCH(21, البيانات_الأساسية!$I:$I, 0)), "") -> 0
B34: =IFERROR(INDEX(البيانات_الأساسية!A:A, MATCH(22, البيانات_الأساسية!$I:$I, 0)), "") -> 0 | C34: =IFERROR(INDEX(البيانات_الأساسية!B:B, MATCH(22, البيانات_الأساسية!$I:$I, 0)), "") -> 0 | D34: =IFERROR(INDEX(البيانات_الأساسية!C:C, MATCH(22, البيانات_الأساسية!$I:$I, 0)), "") -> 0 | E34: =IFERROR(INDEX(البيانات_الأساسية!D:D, MATCH(22, البيانات_الأساسية!$I:$I, 0)), "") -> 0 | F34: =IFERROR(INDEX(البيانات_الأساسية!E:E, MATCH(22, البيانات_الأساسية!$I:$I, 0)), "") -> 0 | G34: =IFERROR(INDEX(البيانات_الأساسية!F:F, MATCH(22, البيانات_الأساسية!$I:$I, 0)), "") -> 0 | H34: =IFERROR(INDEX(البيانات_الأساسية!G:G, MATCH(22, البيانات_الأساسية!$I:$I, 0)), "") -> 0
B35: =IFERROR(INDEX(البيانات_الأساسية!A:A, MATCH(23, البيانات_الأساسية!$I:$I, 0)), "") -> 0 | C35: =IFERROR(INDEX(البيانات_الأساسية!B:B, MATCH(23, البيانات_الأساسية!$I:$I, 0)), "") -> 0 | D35: =IFERROR(INDEX(البيانات_الأساسية!C:C, MATCH(23, البيانات_الأساسية!$I:$I, 0)), "") -> 0 | E35: =IFERROR(INDEX(البيانات_الأساسية!D:D, MATCH(23, البيانات_الأساسية!$I:$I, 0)), "") -> 0 | F35: =IFERROR(INDEX(البيانات_الأساسية!E:E, MATCH(23, البيانات_الأساسية!$I:$I, 0)), "") -> 0 | G35: =IFERROR(INDEX(البيانات_الأساسية!F:F, MATCH(23, البيانات_الأساسية!$I:$I, 0)), "") -> 0 | H35: =IFERROR(INDEX(البيانات_الأساسية!G:G, MATCH(23, البيانات_الأساسية!$I:$I, 0)), "") -> 0
B36: =IFERROR(INDEX(البيانات_الأساسية!A:A, MATCH(24, البيانات_الأساسية!$I:$I, 0)), "") -> 0 | C36: =IFERROR(INDEX(البيانات_الأساسية!B:B, MATCH(24, البيانات_الأساسية!$I:$I, 0)), "") -> 0 | D36: =IFERROR(INDEX(البيانات_الأساسية!C:C, MATCH(24, البيانات_الأساسية!$I:$I, 0)), "") -> 0 | E36: =IFERROR(INDEX(البيانات_الأساسية!D:D, MATCH(24, البيانات_الأساسية!$I:$I, 0)), "") -> 0 | F36: =IFERROR(INDEX(البيانات_الأساسية!E:E, MATCH(24, البيانات_الأساسية!$I:$I, 0)), "") -> 0 | G36: =IFERROR(INDEX(البيانات_الأساسية!F:F, MATCH(24, البيانات_الأساسية!$I:$I, 0)), "") -> 0 | H36: =IFERROR(INDEX(البيانات_الأساسية!G:G, MATCH(24, البيانات_الأساسية!$I:$I, 0)), "") -> 0
B37: =IFERROR(INDEX(البيانات_الأساسية!A:A, MATCH(25, البيانات_الأساسية!$I:$I, 0)), "") -> 0 | C37: =IFERROR(INDEX(البيانات_الأساسية!B:B, MATCH(25, البيانات_الأساسية!$I:$I, 0)), "") -> 0 | D37: =IFERROR(INDEX(البيانات_الأساسية!C:C, MATCH(25, البيانات_الأساسية!$I:$I, 0)), "") -> 0 | E37: =IFERROR(INDEX(البيانات_الأساسية!D:D, MATCH(25, البيانات_الأساسية!$I:$I, 0)), "") -> 0 | F37: =IFERROR(INDEX(البيانات_الأساسية!E:E, MATCH(25, البيانات_الأساسية!$I:$I, 0)), "") -> 0 | G37: =IFERROR(INDEX(البيانات_الأساسية!F:F, MATCH(25, البيانات_الأساسية!$I:$I, 0)), "") -> 0 | H37: =IFERROR(INDEX(البيانات_الأساسية!G:G, MATCH(25, البيانات_الأساسية!$I:$I, 0)), "") -> 0
B38: =IFERROR(INDEX(البيانات_الأساسية!A:A, MATCH(26, البيانات_الأساسية!$I:$I, 0)), "") -> 0 | C38: =IFERROR(INDEX(البيانات_الأساسية!B:B, MATCH(26, البيانات_الأساسية!$I:$I, 0)), "") -> 0 | D38: =IFERROR(INDEX(البيانات_الأساسية!C:C, MATCH(26, البيانات_الأساسية!$I:$I, 0)), "") -> 0 | E38: =IFERROR(INDEX(البيانات_الأساسية!D:D, MATCH(26, البيانات_الأساسية!$I:$I, 0)), "") -> 0 | F38: =IFERROR(INDEX(البيانات_الأساسية!E:E, MATCH(26, البيانات_الأساسية!$I:$I, 0)), "") -> 0 | G38: =IFERROR(INDEX(البيانات_الأساسية!F:F, MATCH(26, البيانات_الأساسية!$I:$I, 0)), "") -> 0 | H38: =IFERROR(INDEX(البيانات_الأساسية!G:G, MATCH(26, البيانات_الأساسية!$I:$I, 0)), "") -> 0
B39: =IFERROR(INDEX(البيانات_الأساسية!A:A, MATCH(27, البيانات_الأساسية!$I:$I, 0)), "") -> 0 | C39: =IFERROR(INDEX(البيانات_الأساسية!B:B, MATCH(27, البيانات_الأساسية!$I:$I, 0)), "") -> 0 | D39: =IFERROR(INDEX(البيانات_الأساسية!C:C, MATCH(27, البيانات_الأساسية!$I:$I, 0)), "") -> 0 | E39: =IFERROR(INDEX(البيانات_الأساسية!D:D, MATCH(27, البيانات_الأساسية!$I:$I, 0)), "") -> 0 | F39: =IFERROR(INDEX(البيانات_الأساسية!E:E, MATCH(27, البيانات_الأساسية!$I:$I, 0)), "") -> 0 | G39: =IFERROR(INDEX(البيانات_الأساسية!F:F, MATCH(27, البيانات_الأساسية!$I:$I, 0)), "") -> 0 | H39: =IFERROR(INDEX(البيانات_الأساسية!G:G, MATCH(27, البيانات_الأساسية!$I:$I, 0)), "") -> 0
B40: =IFERROR(INDEX(البيانات_الأساسية!A:A, MATCH(28, البيانات_الأساسية!$I:$I, 0)), "") -> 0 | C40: =IFERROR(INDEX(البيانات_الأساسية!B:B, MATCH(28, البيانات_الأساسية!$I:$I, 0)), "") -> 0 | D40: =IFERROR(INDEX(البيانات_الأساسية!C:C, MATCH(28, البيانات_الأساسية!$I:$I, 0)), "") -> 0 | E40: =IFERROR(INDEX(البيانات_الأساسية!D:D, MATCH(28, البيانات_الأساسية!$I:$I, 0)), "") -> 0 | F40: =IFERROR(INDEX(البيانات_الأساسية!E:E, MATCH(28, البيانات_الأساسية!$I:$I, 0)), "") -> 0 | G40: =IFERROR(INDEX(البيانات_الأساسية!F:F, MATCH(28, البيانات_الأساسية!$I:$I, 0)), "") -> 0 | H40: =IFERROR(INDEX(البيانات_الأساسية!G:G, MATCH(28, البيانات_الأساسية!$I:$I, 0)), "") -> 0
B41: =IFERROR(INDEX(البيانات_الأساسية!A:A, MATCH(29, البيانات_الأساسية!$I:$I, 0)), "") -> 0 | C41: =IFERROR(INDEX(البيانات_الأساسية!B:B, MATCH(29, البيانات_الأساسية!$I:$I, 0)), "") -> 0 | D41: =IFERROR(INDEX(البيانات_الأساسية!C:C, MATCH(29, البيانات_الأساسية!$I:$I, 0)), "") -> 0 | E41: =IFERROR(INDEX(البيانات_الأساسية!D:D, MATCH(29, البيانات_الأساسية!$I:$I, 0)), "") -> 0 | F41: =IFERROR(INDEX(البيانات_الأساسية!E:E, MATCH(29, البيانات_الأساسية!$I:$I, 0)), "") -> 0 | G41: =IFERROR(INDEX(البيانات_الأساسية!F:F, MATCH(29, البيانات_الأساسية!$I:$I, 0)), "") -> 0 | H41: =IFERROR(INDEX(البيانات_الأساسية!G:G, MATCH(29, البيانات_الأساسية!$I:$I, 0)), "") -> 0
B42: =IFERROR(INDEX(البيانات_الأساسية!A:A, MATCH(30, البيانات_الأساسية!$I:$I, 0)), "") -> 0 | C42: =IFERROR(INDEX(البيانات_الأساسية!B:B, MATCH(30, البيانات_الأساسية!$I:$I, 0)), "") -> 0 | D42: =IFERROR(INDEX(البيانات_الأساسية!C:C, MATCH(30, البيانات_الأساسية!$I:$I, 0)), "") -> 0 | E42: =IFERROR(INDEX(البيانات_الأساسية!D:D, MATCH(30, البيانات_الأساسية!$I:$I, 0)), "") -> 0 | F42: =IFERROR(INDEX(البيانات_الأساسية!E:E, MATCH(30, البيانات_الأساسية!$I:$I, 0)), "") -> 0 | G42: =IFERROR(INDEX(البيانات_الأساسية!F:F, MATCH(30, البيانات_الأساسية!$I:$I, 0)), "") -> 0 | H42: =IFERROR(INDEX(البيانات_الأساسية!G:G, MATCH(30, البيانات_الأساسية!$I:$I, 0)), "") -> 0
B43: =IFERROR(INDEX(البيانات_الأساسية!A:A, MATCH(31, البيانات_الأساسية!$I:$I, 0)), "") -> 0 | C43: =IFERROR(INDEX(البيانات_الأساسية!B:B, MATCH(31, البيانات_الأساسية!$I:$I, 0)), "") -> 0 | D43: =IFERROR(INDEX(البيانات_الأساسية!C:C, MATCH(31, البيانات_الأساسية!$I:$I, 0)), "") -> 0 | E43: =IFERROR(INDEX(البيانات_الأساسية!D:D, MATCH(31, البيانات_الأساسية!$I:$I, 0)), "") -> 0 | F43: =IFERROR(INDEX(البيانات_الأساسية!E:E, MATCH(31, البيانات_الأساسية!$I:$I, 0)), "") -> 0 | G43: =IFERROR(INDEX(البيانات_الأساسية!F:F, MATCH(31, البيانات_الأساسية!$I:$I, 0)), "") -> 0 | H43: =IFERROR(INDEX(البيانات_الأساسية!G:G, MATCH(31, البيانات_الأساسية!$I:$I, 0)), "") -> 0
B44: =IFERROR(INDEX(البيانات_الأساسية!A:A, MATCH(32, البيانات_الأساسية!$I:$I, 0)), "") -> 0 | C44: =IFERROR(INDEX(البيانات_الأساسية!B:B, MATCH(32, البيانات_الأساسية!$I:$I, 0)), "") -> 0 | D44: =IFERROR(INDEX(البيانات_الأساسية!C:C, MATCH(32, البيانات_الأساسية!$I:$I, 0)), "") -> 0 | E44: =IFERROR(INDEX(البيانات_الأساسية!D:D, MATCH(32, البيانات_الأساسية!$I:$I, 0)), "") -> 0 | F44: =IFERROR(INDEX(البيانات_الأساسية!E:E, MATCH(32, البيانات_الأساسية!$I:$I, 0)), "") -> 0 | G44: =IFERROR(INDEX(البيانات_الأساسية!F:F, MATCH(32, البيانات_الأساسية!$I:$I, 0)), "") -> 0 | H44: =IFERROR(INDEX(البيانات_الأساسية!G:G, MATCH(32, البيانات_الأساسية!$I:$I, 0)), "") -> 0
B45: =IFERROR(INDEX(البيانات_الأساسية!A:A, MATCH(33, البيانات_الأساسية!$I:$I, 0)), "") -> 0 | C45: =IFERROR(INDEX(البيانات_الأساسية!B:B, MATCH(33, البيانات_الأساسية!$I:$I, 0)), "") -> 0 | D45: =IFERROR(INDEX(البيانات_الأساسية!C:C, MATCH(33, البيانات_الأساسية!$I:$I, 0)), "") -> 0 | E45: =IFERROR(INDEX(البيانات_الأساسية!D:D, MATCH(33, البيانات_الأساسية!$I:$I, 0)), "") -> 0 | F45: =IFERROR(INDEX(البيانات_الأساسية!E:E, MATCH(33, البيانات_الأساسية!$I:$I, 0)), "") -> 0 | G45: =IFERROR(INDEX(البيانات_الأساسية!F:F, MATCH(33, البيانات_الأساسية!$I:$I, 0)), "") -> 0 | H45: =IFERROR(INDEX(البيانات_الأساسية!G:G, MATCH(33, البيانات_الأساسية!$I:$I, 0)), "") -> 0
B46: =IFERROR(INDEX(البيانات_الأساسية!A:A, MATCH(34, البيانات_الأساسية!$I:$I, 0)), "") -> 0 | C46: =IFERROR(INDEX(البيانات_الأساسية!B:B, MATCH(34, البيانات_الأساسية!$I:$I, 0)), "") -> 0 | D46: =IFERROR(INDEX(البيانات_الأساسية!C:C, MATCH(34, البيانات_الأساسية!$I:$I, 0)), "") -> 0 | E46: =IFERROR(INDEX(البيانات_الأساسية!D:D, MATCH(34, البيانات_الأساسية!$I:$I, 0)), "") -> 0 | F46: =IFERROR(INDEX(البيانات_الأساسية!E:E, MATCH(34, البيانات_الأساسية!$I:$I, 0)), "") -> 0 | G46: =IFERROR(INDEX(البيانات_الأساسية!F:F, MATCH(34, البيانات_الأساسية!$I:$I, 0)), "") -> 0 | H46: =IFERROR(INDEX(البيانات_الأساسية!G:G, MATCH(34, البيانات_الأساسية!$I:$I, 0)), "") -> 0
...
